Workbook

Sheet Exp1_Tempreintervalof10mins_1
A2: DATE/TIME | B2: Pimoroni MLX90640 (degree Celsius) | C2: RS PRO T-10 (degree Celsius) | D2: RobotShop MLX90640 (degree Celsius) | E2: Actual Temp | F2: DISTANCE (M) | G2: AMBIENT TEMP (degree Celsius)
A3: 15-08-24/ 11:10AM | B3: 34.4 | C3: 32 | D3: 34.4 | E3: 36.8 | F3: 1 | G3: 25.7
A4: 15-08-24/ 11:20AM | B4: 32.2 | C4: 29 | D4: 32.2 | E4: 36.8 | F4: 2 | G4: 25.8
A5: 15-08-24/ 11:30AM | B5: 31.5 | C5: 21.5 | D5: 31 | E5: 36.8 | F5: 3 | G5: 25.8
A6: 15-08-24/ 11:40AM | B6: 30.5 | C6: 21.3 | D6: 30 | E6: 36.8 | F6: 4 | G6: 26
A7: 15-08-24/ 11:50AM | B7: 30 | C7: 21 | D7: 30.9 | E7: 36.8 | F7: 5 | G7: 26
A11: Actual Temperature = 36.8

Sheet Exp1_Tempreadintervalof2min_2
A2: DATE/TIME | B2: Pimoroni MLX90640 (degree Celsius) | C2: RS PRO T-10 (degree Celsius) | D2: RobotShop MLX90640 (degree Celsius) | E2: Actual Temp | F2: DISTANCE (M) | G2: AMBIENT TEMP (degree Celsius)
A3: 15-08-24/ 11:56 | B3: 31.5 | C3: 28 | D3: 31 | E3: 36.5 | F3: 5 | G3: 26.2
A4: 15-08-24/ 11:58 | B4: 31.5 | C4: 29.2 | D4: 31 | E4: 36.5 | F4: 4 | G4: 26.2
A5: 15-08-24/ 12:00 | B5: 32.5 | C5: 29.5 | D5: 32 | E5: 36.5 | F5: 3 | G5: 26.2
A6: 15-08-24/ 12:02 | B6: 32.9 | C6: 31 | D6: 32.9 | E6: 36.5 | F6: 2 | G6: 26.2
A7: 15-08-24/ 12:04 | B7: 34.5 | C7: 33 | D7: 34.5 | E7: 36.5 | F7: 1 | G7: 26.2
A10: Actual Temp 36.5

Sheet Exp1_Tempreadingradomlypicked_3
A1: DATE/TIME | B1: Pimoroni MLX90640 (degree Celsius) | C1: RS PRO T-10 (degree Celsius) | D1: RobotShop MLX90640 (degree Celsius) | E1: Actual Temp | F1: DISTANCE (M) | G1: AMBIENT TEMP (degree Celsius)
A2: 15-08-24/ 13:50 | B2: 33.5 | C2: 31 | D2: 33.5 | E2: 36.7 | F2: 1 | G2: 25
A3: 15-08-24/ 13:53 | B3: 31.5 | C3: 29 | D3: 31 | E3: 36.7 | F3: 2 | G3: 25
A4: 15-08-24/ 13:54 | B4: 29.2 | C4: 26.5 | D4: 29 | E4: 36.7 | F4: 3 | G4: 25
A5: 15-08-24/ 13:57 | B5: 29 | C5: 22 | D5: 29 | E5: 36.7 | F5: 4 | G5: 25
A6: 15-08-24/ 14:00 | B6: 28 | C6: 21 | D6: 28 | E6: 36.7 | F6: 5 | G6: 25.1
A9: Actual Temp 36.8

Sheet Exp1_bodydarkskinemissivity1_4
A1: DATE/TIME | B1: Pimoroni MLX90640 (degree Celsius) | C1: RS PRO T-10 (degree Celsius) | D1: RobotShop MLX90640 (degree Celsius) | E1: Actual Temp | F1: DISTANCE (M) | G1: AMBIENT TEMP (degree Celsius)
A2: 15-08-24/ 14:08 | B2: 34.75 | C2: 30.1 | D2: 33.5 | E2: 36 | F2: 1 | G2: 25.7
A3: 15-08-24/ 14:12 | B3: 32.25 | C3: 28.4 | D3: 31.75 | E3: 36 | F3: 2 | G3: 25.7
A4: 15-08-24/ 14.14 | B4: 30.75 | C4: 28.7 | D4: 30.25 | E4: 36 | F4: 3 | G4: 25.7
A5: 15-08-24/ 14:16 | B5: 30.25 | C5: 25.3 | D5: 29.25 | E5: 36 | F5: 4 | G5: 25.7
A6: 15-08-24/ 14:17 | B6: 30 | C6: 25 | D6: 29.75 | E6: 36 | F6: 5 | G6: 25.7
A9: Average | B9: =AVERAGE(Table20[Pimoroni MLX90640 (degree Celsius)]) -> 31.6 | C9: =AVERAGE(Table20[RS PRO T-10 (degree Celsius)]) -> 27.5 | D9: =AVERAGE(Table20[RobotShop MLX90640 (degree Celsius)]) -> 30.9
A12: Actual Temp 36.8
B13: Dack skin without Glasses on , under artificial home illumination

Sheet Exp1_Bodydarkskinemissivity_5
A1: DATE/TIME | B1: Pimoroni MLX90640 (degree Celsius) | C1: RS PRO T-10 (degree Celsius) | D1: RobotShop MLX90640 (degree Celsius) | E1: Actual Temp | F1: DISTANCE (M) | G1: AMBIENT TEMP (degree Celsius)
A2: 15-08-24/ 14:18 | B2: 34.5 | C2: 30.4 | D2: 33.25 | E2: 36 | F2: 1 | G2: 25.8
A3: 15-08-24/ 14:20 | B3: 31.75 | C3: 29.9 | D3: 31 | E3: 36 | F3: 2 | G3: 25.7
A4: 15-08-24/ 14.21 | B4: 30.5 | C4: 28.7 | D4: 30.25 | E4: 36 | F4: 3 | G4: 25.7
A5: 15-08-24/ 14:22 | B5: 30.25 | C5: 27.7 | D5: 29.75 | E5: 36 | F5: 4 | G5: 25.7
A6: 15-08-24/ 14:23 | B6: 29.75 | C6: 25.7 | D6: 29.75 | E6: 36 | F6: 5 | G6: 25.7
A9: Average | B9: =AVERAGE(Table21[Pimoroni MLX90640 (degree Celsius)]) -> 31.35 | C9: =AVERAGE(Table21[RS PRO T-10 (degree Celsius)]) -> 28.48 | D9: =AVERAGE(Table21[RobotShop MLX90640 (degree Celsius)]) -> 30.8
A11: Actual Temp 36.8
B12: Dack skin with Glasses on , under artificial home illumination

Sheet Exp1_bodylightskinemmisivity_6
A1: DATE/TIME | B1: Pimoroni MLX90640 (degree Celsius) | C1: RS PRO T-10 (degree Celsius) | D1: RobotShop MLX90640 (degree Celsius) | E1: Actual Temp | F1: DISTANCE (M) | G1: AMBIENT TEMP (degree Celsius)
A2: 15-08-24/ 14:45 | B2: 33.75 | C2: 30.3 | D2: 33.5 | E2: 36.8 | F2: 1 | G2: 25.8
A3: 15-08-24/ 14:47 | B3: 31.5 | C3: 29.3 | D3: 31.7 | E3: 36.8 | F3: 2 | G3: 25.7
A4: 15-08-24/ 14.49 | B4: 30.2 | C4: 28.8 | D4: 30 | E4: 36.8 | F4: 3 | G4: 25.7
A5: 15-08-24/ 14:50 | B5: 29.5 | C5: 28.3 | D5: 29 | E5: 36.8 | F5: 4 | G5: 25.7
A6: 15-08-24/ 14:52 | B6: 28.5 | C6: 28 | D6: 29 | E6: 36.8 | F6: 5 | G6: 25.7
A9: Average | B9: =AVERAGE(Table22[Pimoroni MLX90640 (degree Celsius)]) -> 30.69 | C9: =AVERAGE(Table22[RS PRO T-10 (degree Celsius)]) -> 28.94 | D9: =AVERAGE(Table22[RobotShop MLX90640 (degree Celsius)]) -> 30.64
A11: Actual Temp 36.8
C12: Light skin with Glasses on , under artificial home illumination

Sheet Exp1_bodylightskinemmisivity1_7
A1: DATE/TIME | B1: Pimoroni MLX90640 (degree Celsius) | C1: RS PRO T-10 (degree Celsius) | D1: RobotShop MLX90640 (degree Celsius) | E1: Actual Temp | F1: DISTANCE (M) | G1: AMBIENT TEMP (degree Celsius)
A2: 15-08-24/ 14:33 | B2: 32.5 | C2: 29.8 | D2: 32.5 | E2: 36.2 | F2: 1 | G2: 25.8
A3: 15-08-24/ 14:34 | B3: 30.75 | C3: 28.2 | D3: 30.5 | E3: 36.2 | F3: 2 | G3: 25.7
A4: 15-08-24/ 14:36 | B4: 29.7 | C4: 25.9 | D4: 30 | E4: 36.2 | F4: 3 | G4: 25.7
A5: 15-08-24/ 14:38 | B5: 28.75 | C5: 25.2 | D5: 29 | E5: 36.2 | F5: 4 | G5: 25.7
A6: 15-08-24/ 14:41 | B6: 24.1 | C6: 20.2 | D6: 24 | E6: 36.2 | F6: 5 | G6: 25.7
A9: Average | B9: =AVERAGE(Table23[Pimoroni MLX90640 (degree Celsius)]) -> 29.16 | C9: =AVERAGE(Table23[RS PRO T-10 (degree Celsius)]) -> 25.86 | D9: =AVERAGE(Table23[RobotShop MLX90640 (degree Celsius)]) -> 29.2
A13: Actual Temp 36.8
B14: Light skin without Glasses on , under artificial home illumination

Sheet Exp1_Lightskinlowtempnaturalh_8
A1: DATE/TIME | B1: Pimoroni MLX90640 (degree Celsius) | C1: RS PRO T-10 (degree Celsius) | D1: RobotShop MLX90640 (degree Celsius) | E1: Actual Temp | F1: DISTANCE (M) | G1: AMBIENT TEMP (degree Celsius)
A2: 15-08-24/ 16:08 | B2: 32 | C2: 31.6 | D2: 32 | E2: 36.1 | F2: 1 | G2: 20.2
A3: 15-08-24/ 16:10 | B3: 28.75 | C3: 30 | D3: 29 | E3: 36.1 | F3: 2 | G3: 20.2
A4: 15-08-24/ 16:12 | B4: 27.8 | C4: 29 | D4: 27.25 | E4: 36.1 | F4: 3 | G4: 20.6
A5: 15-08-24/ 16:13 | B5: 26.5 | C5: 28.2 | D5: 26.5 | E5: 36.1 | F5: 4 | G5: 21
A6: 15-08-24/ 16:14 | B6: 25.2 | C6: 27.5 | D6: 25 | E6: 36.1 | F6: 5 | G6: 21
A9: Average | B9: =AVERAGE(Table24[Pimoroni MLX90640 (degree Celsius)]) -> 28.05 | C9: =AVERAGE(Table24[RS PRO T-10 (degree Celsius)]) -> 29.26 | D9: =AVERAGE(Table24[RobotShop MLX90640 (degree Celsius)]) -> 27.95
A12: Actual Temp 36.8
B13: Light skin, low temp, natural home illumination

Sheet Exp1_Darkskinlowtempnaturalho_9
A1: DATE/TIME | B1: Pimoroni MLX90640 (degree Celsius) | C1: RS PRO T-10 (degree Celsius) | D1: RobotShop MLX90640 (degree Celsius) | E1: Actual Temp | F1: DISTANCE (M) | G1: AMBIENT TEMP (degree Celsius)
A2: 15-08-24/ 16:20 | B2: 32.75 | C2: 30.9 | D2: 31.5 | E2: 36.8 | F2: 1 | G2: 21.7
A3: 15-08-24/ 16:21 | B3: 29.25 | C3: 29.5 | D3: 28.5 | E3: 36.8 | F3: 2 | G3: 21.9
A4: 15-08-24/ 16:22 | B4: 28.25 | C4: 28.8 | D4: 28.5 | E4: 36.8 | F4: 3 | G4: 21.9
A5: 15-08-24/ 16:23 | B5: 27.25 | C5: 28.5 | D5: 27 | E5: 36.8 | F5: 4 | G5: 22
A6: 15-08-24/ 16:24 | B6: 27 | C6: 28.5 | D6: 26.25 | E6: 36.8 | F6: 5 | G6: 22.1
A9: Average | B9: =AVERAGE(Table25[Pimoroni MLX90640 (degree Celsius)]) -> 28.9 | C9: =AVERAGE(Table25[RS PRO T-10 (degree Celsius)]) -> 29.24 | D9: =AVERAGE(Table25[RobotShop MLX90640 (degree Celsius)]) -> 28.35
A14: Actual Temp 36.80
B15: Dark skin, low temp, natural home illumination

Sheet Exp1_Darksknlowtepartificial_10
A1: DATE/TIME | B1: Pimoroni MLX90640 (degree Celsius) | C1: RS PRO T-10 (degree Celsius) | D1: RobotShop MLX90640 (degree Celsius) | E1: Actual Temp | F1: DISTANCE (M) | G1: AMBIENT TEMP (degree Celsius)
A2: 15-08-24/ 16:43 | B2: 32.5 | C2: 30.4 | D2: 32.25 | E2: 35.6 | F2: 1 | G2: 22.6
A3: 15-08-24/ 16:44 | B3: 29.5 | C3: 29.6 | D3: 29.75 | E3: 35.6 | F3: 2 | G3: 22.6
A4: 15-08-24/ 16:45 | B4: 28.75 | C4: 28 | D4: 28.75 | E4: 35.6 | F4: 3 | G4: 22.8
A5: 15-08-24/ 16:47 | B5: 27.75 | C5: 26.2 | D5: 26.2 | E5: 35.6 | F5: 4 | G5: 22.8
A6: 15-08-24/ 16:49 | B6: 26.75 | C6: 26.5 | D6: 27 | E6: 35.6 | F6: 5 | G6: 22.8
A9: Average | B9: =AVERAGE(Table26[Pimoroni MLX90640 (degree Celsius)]) -> 29.05 | C9: =AVERAGE(Table26[RS PRO T-10 (degree Celsius)]) -> 28.14 | D9: =AVERAGE(Table26[RobotShop MLX90640 (degree Celsius)]) -> 28.79
A13: Actual Temp 35.6
B15: dark skin, low temp, artificial home illumination

Sheet Exp1_lghtsknlowtempartificia_11
A1: DATE/TIME | B1: Pimoroni MLX90640 (degree Celsius) | C1: RS PRO T-10 (degree Celsius) | D1: RobotShop MLX90640 (degree Celsius) | E1: Actual Temp | F1: DISTANCE (M) | G1: AMBIENT TEMP (degree Celsius)
A2: 15-08-24/ 16:53 | B2: 32.2 | C2: 30.1 | D2: 31.5 | E2: 36.9 | F2: 1 | G2: 22.6
A3: 15-08-24/ 16:54 | B3: 30.5 | C3: 30 | D3: 29.25 | E3: 36.9 | F3: 2 | G3: 22.6
A4: 15-08-24/ 16:55 | B4: 29.75 | C4: 28.8 | D4: 28.5 | E4: 36.9 | F4: 3 | G4: 22.8
A5: 15-08-24/ 16:56 | B5: 28.75 | C5: 27.5 | D5: 28 | E5: 36.9 | F5: 4 | G5: 22.8
A6: 15-08-24/ 16:57 | B6: 28.25 | C6: 27.4 | D6: 27.5 | E6: 36.9 | F6: 5 | G6: 22.8
A9: Average | B9: =AVERAGE(Table16[Pimoroni MLX90640 (degree Celsius)]) -> 29.89 | C9: =AVERAGE(Table16[RS PRO T-10 (degree Celsius)]) -> 28.76 | D9: =AVERAGE(Table16[RobotShop MLX90640 (degree Celsius)]) -> 28.95
A13: Actual Temp 36.9
B14: light skin, low temp, artificial home illumination

Sheet Exp1_CategoryofTempReadingfromP
A1: Column1 | B1: Column2 | C1: Column3 | D1: Column4 | E1: Column5 | F1: Column6 | G1: Column7 | H1: Column8 | I1: Column9 | J1: Column10
A2: Category of Temp reading from Pimoroni MLX90640 (degree Celsius) | B2: Temp Readings at 1 Metre | D2: Temp Readings at 2 Metres | F2: Temp Readings at 3 Metres | H2: Temp Readings at 4 Metres | J2: Temp Readings at 5 Metres
A3: Temp reading interval of 10mins | B3: =Exp1_Tempreintervalof10mins_1!B3 -> 34.4 | D3: =Exp1_Tempreintervalof10mins_1!B4 -> 32.2 | F3: =Exp1_Tempreintervalof10mins_1!B5 -> 31.5 | H3: =Exp1_Tempreintervalof10mins_1!B6 -> 30.5 | J3: =Exp1_Tempreintervalof10mins_1!B7 -> 30
A4: Temp reading interval of 2mins | B4: =Exp1_Tempreadintervalof2min_2!B7 -> 34.5 | D4: =Exp1_Tempreadintervalof2min_2!B6 -> 32.9 | F4: =Exp1_Tempreadintervalof2min_2!B5 -> 32.5 | H4: =Exp1_Tempreadintervalof2min_2!B6 -> 32.9 | J4: =Exp1_Tempreadintervalof2min_2!B3 -> 31.5
A5: Temp reading radomly picked | B5: =Exp1_Tempreadingradomlypicked_3!B2 -> 33.5 | D5: =Exp1_Tempreadingradomlypicked_3!B3 -> 31.5 | F5: =Exp1_Tempreadingradomlypicked_3!B4 -> 29.2 | H5: =Exp1_Tempreadingradomlypicked_3!B5 -> 29 | J5: =Exp1_Tempreadingradomlypicked_3!B6 -> 28
A6: Dack emissivity skin without Glasses on , under artificial home illumination | B6: =Exp1_bodydarkskinemissivity1_4!B2 -> 34.75 | D6: =Exp1_bodydarkskinemissivity1_4!B3 -> 32.25 | F6: =Exp1_bodydarkskinemissivity1_4!B4 -> 30.75 | H6: =Exp1_bodydarkskinemissivity1_4!B5 -> 30.25 | J6: =Exp1_bodydarkskinemissivity1_4!B6 -> 30
A7: Dack skin emissivity with Glasses on , under artificial home illumination | B7: =Exp1_Bodydarkskinemissivity_5!B2 -> 34.5 | D7: =Exp1_Bodydarkskinemissivity_5!B3 -> 31.75 | F7: =Exp1_Bodydarkskinemissivity_5!B4 -> 30.5 | H7: =Exp1_Bodydarkskinemissivity_5!B5 -> 30.25 | J7: =Exp1_Bodydarkskinemissivity_5!B6 -> 29.75
A8: Light skin emissivity with Glasses on , under artificial home illumination | B8: =Exp1_bodylightskinemmisivity_6!B2 -> 33.75 | D8: =Exp1_bodylightskinemmisivity_6!B3 -> 31.5 | F8: =Exp1_bodylightskinemmisivity_6!B4 -> 30.2 | H8: =Exp1_bodylightskinemmisivity_6!B5 -> 29.5 | J8: =Exp1_bodylightskinemmisivity_6!B6 -> 28.5
A9: Light skin emissivity without Glasses on, under artificial home illumination | B9: =Exp1_bodylightskinemmisivity1_7!B2 -> 32.5 | D9: =Exp1_bodylightskinemmisivity1_7!B3 -> 30.75 | F9: =Exp1_bodylightskinemmisivity1_7!B4 -> 29.7 | H9: =Exp1_bodylightskinemmisivity1_7!B5 -> 28.75 | J9: =Exp1_bodylightskinemmisivity1_7!B6 -> 24.1
A10: Light skin emissivity, low temp, natural home illumination | B10: =Exp1_Lightskinlowtempnaturalh_8!B2 -> 32 | D10: =Exp1_Lightskinlowtempnaturalh_8!B3 -> 28.75 | F10: =Exp1_Lightskinlowtempnaturalh_8!B4 -> 27.8 | H10: =Exp1_Lightskinlowtempnaturalh_8!B5 -> 26.5 | J10: =Exp1_Lightskinlowtempnaturalh_8!B6 -> 25.2
A11: Dark skin emissivity, low temp, natural home illumination | B11: =Exp1_Darkskinlowtempnaturalho_9!B2 -> 32.75 | D11: =Exp1_Darkskinlowtempnaturalho_9!B3 -> 29.25 | F11: =Exp1_Darkskinlowtempnaturalho_9!B4 -> 28.25 | H11: =Exp1_Darkskinlowtempnaturalho_9!B5 -> 27.25 | J11: =Exp1_Darkskinlowtempnaturalho_9!B6 -> 27
A12: Dark skin emissivity, low temp, artificial home illumination | B12: =Exp1_Darksknlowtepartificial_10!B2 -> 32.5 | D12: =Exp1_Darksknlowtepartificial_10!B3 -> 29.5 | F12: =Exp1_Darksknlowtepartificial_10!B4 -> 28.75 | H12: =Exp1_Darksknlowtepartificial_10!B5 -> 27.75 | J12: =Exp1_Darksknlowtepartificial_10!B6 -> 26.75
A13: Light skin emissivity, low temp, artificial home illumination | B13: =Exp1_lghtsknlowtempartificia_11!B2 -> 32.2 | D13: =Exp1_lghtsknlowtempartificia_11!B3 -> 30.5 | F13: =Exp1_lghtsknlowtempartificia_11!B4 -> 29.75 | H13: =Exp1_lghtsknlowtempartificia_11!B5 -> 28.75 | J13: =Exp1_lghtsknlowtempartificia_11!B6 -> 28.25
A14: Mean Temp reading for each distance (Metre) | B14: =AVERAGE(B3:B13) -> 33.395455 | D14: =AVERAGE(D3:D13) -> 30.986364 | F14: =AVERAGE(F3:F13) -> 29.9 | H14: =AVERAGE(H3:H13) -> 29.218182 | J14: =AVERAGE(J3:J13) -> 28.095455

Sheet Exp1_CategoriesofTempreadingbyR
A1: Column1 | B1: Column2 | C1: Column3 | D1: Column4 | E1: Column5 | F1: Column6 | G1: Column7 | H1: Column8 | I1: Column9 | J1: Column10
A2: Category of Temp reading from RS PRO T-10 (Degree Celsius) | B2: Temp Readings at 1 Metre | D2: Temp Readings at 2 Metres | F2: Temp Readings at 3 Metres | H2: Temp Readings at 4 Metres | J2: Temp Readings at 5 Metres
A3: Temp reading interval of 10mins | B3: =Exp1_Tempreintervalof10mins_1!C3 -> 32 | D3: =Exp1_Tempreintervalof10mins_1!C4 -> 29 | F3: =Exp1_Tempreintervalof10mins_1!C5 -> 21.5 | H3: =Exp1_Tempreintervalof10mins_1!C6 -> 21.3 | J3: =Exp1_Tempreintervalof10mins_1!C7 -> 21
A4: Temp reading interval of 2mins | B4: =Exp1_Tempreadintervalof2min_2!C7 -> 33 | D4: =Exp1_Tempreadintervalof2min_2!C6 -> 31 | F4: =Exp1_Tempreadintervalof2min_2!C5 -> 29.5 | H4: =Exp1_Tempreadintervalof2min_2!C4 -> 29.2 | J4: =Exp1_Tempreadintervalof2min_2!C3 -> 28
A5: Temp reading radomly picked | B5: =Exp1_Tempreadingradomlypicked_3!C2 -> 31 | D5: =Exp1_Tempreadingradomlypicked_3!C3 -> 29 | F5: =Exp1_Tempreadingradomlypicked_3!C4 -> 26.5 | H5: =Exp1_Tempreadingradomlypicked_3!C5 -> 22 | J5: =Exp1_Tempreadingradomlypicked_3!C6 -> 21
A6: Dack emissivity skin without Glasses on , under artificial home illumination | B6: =Exp1_bodydarkskinemissivity1_4!C2 -> 30.1 | D6: =Exp1_bodydarkskinemissivity1_4!C3 -> 28.4 | F6: =Exp1_bodydarkskinemissivity1_4!C4 -> 28.7 | H6: =Exp1_bodydarkskinemissivity1_4!C5 -> 25.3 | J6: =Exp1_bodydarkskinemissivity1_4!C6 -> 25
A7: Dack skin emissivity with Glasses on , under artificial home illumination | B7: =Exp1_Bodydarkskinemissivity_5!C2 -> 30.4 | D7: =Exp1_Bodydarkskinemissivity_5!C3 -> 29.9 | F7: =Exp1_Bodydarkskinemissivity_5!C4 -> 28.7 | H7: =Exp1_Bodydarkskinemissivity_5!C5 -> 27.7 | J7: =Exp1_Bodydarkskinemissivity_5!C6 -> 25.7
A8: Light skin emissivity with Glasses on , under artificial home illumination | B8: =Exp1_bodylightskinemmisivity_6!C2 -> 30.3 | D8: =Exp1_bodylightskinemmisivity_6!C3 -> 29.3 | F8: =Exp1_bodylightskinemmisivity_6!C4 -> 28.8 | H8: =Exp1_bodylightskinemmisivity_6!C5 -> 28.3 | J8: =Exp1_bodylightskinemmisivity_6!C6 -> 28
A9: Light skin emissivity without Glasses on, under artificial home illumination | B9: =Exp1_bodylightskinemmisivity1_7!C2 -> 29.8 | D9: =Exp1_bodylightskinemmisivity1_7!C3 -> 28.2 | F9: =Exp1_bodylightskinemmisivity1_7!C4 -> 25.9 | H9: =Exp1_bodylightskinemmisivity1_7!C5 -> 25.2 | J9: =Exp1_bodylightskinemmisivity1_7!C6 -> 20.2
A10: Light skin emissivity, low temp, natural home illumination | B10: =Exp1_Lightskinlowtempnaturalh_8!C2 -> 31.6 | D10: =Exp1_Lightskinlowtempnaturalh_8!C3 -> 30 | F10: =Exp1_Lightskinlowtempnaturalh_8!C4 -> 29 | H10: =Exp1_Lightskinlowtempnaturalh_8!C5 -> 28.2 | J10: =Exp1_Lightskinlowtempnaturalh_8!C6 -> 27.5
A11: Dark skin emissivity, low temp, natural home illumination | B11: =Exp1_Darkskinlowtempnaturalho_9!C2 -> 30.9 | D11: =Exp1_Darkskinlowtempnaturalho_9!C3 -> 29.5 | F11: =Exp1_Darkskinlowtempnaturalho_9!C4 -> 28.8 | H11: =Exp1_Darkskinlowtempnaturalho_9!C5 -> 28.5 | J11: =Exp1_Darkskinlowtempnaturalho_9!C6 -> 28.5
A12: Dark skin emissivity, low temp, artificial home illumination | B12: =Exp1_Darksknlowtepartificial_10!C2 -> 30.4 | D12: =Exp1_Darksknlowtepartificial_10!C3 -> 29.6 | F12: =Exp1_Darksknlowtepartificial_10!C4 -> 28 | H12: =Exp1_Darksknlowtepartificial_10!C5 -> 26.2 | J12: =Exp1_Darksknlowtepartificial_10!C6 -> 26.5
A13: Light skin emissivity, low temp, artificial home illumination | B13: =Exp1_lghtsknlowtempartificia_11!C2 -> 30.1 | D13: =Exp1_lghtsknlowtempartificia_11!C3 -> 30 | F13: =Exp1_lghtsknlowtempartificia_11!C4 -> 28.8 | H13: =Exp1_lghtsknlowtempartificia_11!C5 -> 27.5 | J13: =Exp1_lghtsknlowtempartificia_11!C6 -> 27.4
A14: Mean Temp reading for each distance (Metre) | B14: =AVERAGE(B3:B13) -> 30.872727 | D14: =AVERAGE(D3:D13) -> 29.445455 | F14: =AVERAGE(F3:F13) -> 27.654545 | H14: =AVERAGE(H3:H13) -> 26.309091 | J14: =AVERAGE(J3:J13) -> 25.345455

Sheet Exp1_CategoriesofTempreadingRob
A1: Column1 | B1: Column2 | C1: Column3 | D1: Column4 | E1: Column5 | F1: Column6 | G1: Column7 | H1: Column8 | I1: Column9 | J1: Column10
A2: Category of Temp reading from Robotshop MLX90640 (Degree Celsius) | B2: Temp Readings at 1 Metre | D2: Temp Readings at 2 Metres | F2: Temp Readings at 3 Metres | H2: Temp Readings at 4 Metres | J2: Temp Readings at 5 Metres
A3: Temp reading interval of 10mins | B3: =Exp1_Tempreintervalof10mins_1!D3 -> 34.4 | D3: =Exp1_Tempreintervalof10mins_1!D4 -> 32.2 | F3: =Exp1_Tempreintervalof10mins_1!D5 -> 31 | H3: =Exp1_Tempreintervalof10mins_1!D6 -> 30 | J3: =Exp1_Tempreintervalof10mins_1!D7 -> 30.9
A4: Temp reading interval of 2mins | B4: =Exp1_Tempreadintervalof2min_2!D7 -> 34.5 | D4: =Exp1_Tempreadintervalof2min_2!D6 -> 32.9 | F4: =Exp1_Tempreadintervalof2min_2!D5 -> 32 | H4: =Exp1_Tempreadintervalof2min_2!D4 -> 31 | J4: =Exp1_Tempreadintervalof2min_2!D3 -> 31
A5: Temp reading radomly picked | B5: =Exp1_Tempreadingradomlypicked_3!D2 -> 33.5 | D5: =Exp1_Tempreadingradomlypicked_3!D3 -> 31 | F5: =Exp1_Tempreadingradomlypicked_3!D4 -> 29 | H5: =Exp1_Tempreadingradomlypicked_3!D5 -> 29 | J5: =Exp1_Tempreadingradomlypicked_3!D6 -> 28
A6: Dack emissivity skin without Glasses on , under artificial home illumination | B6: =Exp1_bodydarkskinemissivity1_4!D2 -> 33.5 | D6: =Exp1_bodydarkskinemissivity1_4!D3 -> 31.75 | F6: =Exp1_bodydarkskinemissivity1_4!D4 -> 30.25 | H6: =Exp1_bodydarkskinemissivity1_4!D5 -> 29.25 | J6: =Exp1_bodydarkskinemissivity1_4!D6 -> 29.75
A7: Dack skin emissivity with Glasses on , under artificial home illumination | B7: =Exp1_Bodydarkskinemissivity_5!D2 -> 33.25 | D7: =Exp1_Bodydarkskinemissivity_5!D3 -> 31 | F7: =Exp1_Bodydarkskinemissivity_5!D4 -> 30.25 | H7: =Exp1_Bodydarkskinemissivity_5!D5 -> 29.75 | J7: =Exp1_Bodydarkskinemissivity_5!D6 -> 29.75
A8: Light skin emissivity with Glasses on , under artificial home illumination | B8: =Exp1_bodylightskinemmisivity_6!D2 -> 33.5 | D8: =Exp1_bodylightskinemmisivity_6!D3 -> 31.7 | F8: =Exp1_bodylightskinemmisivity_6!D4 -> 30 | H8: =Exp1_bodylightskinemmisivity_6!D5 -> 29 | J8: =Exp1_bodylightskinemmisivity_6!D6 -> 29
A9: Light skin emissivity without Glasses on, under artificial home illumination | B9: =Exp1_bodylightskinemmisivity1_7!D2 -> 32.5 | D9: =Exp1_bodylightskinemmisivity1_7!D3 -> 30.5 | F9: =Exp1_bodylightskinemmisivity1_7!D4 -> 30 | H9: =Exp1_bodylightskinemmisivity1_7!D5 -> 29 | J9: =Exp1_bodylightskinemmisivity1_7!D6 -> 24
A10: Light skin emissivity, low temp, natural home illumination | B10: =Exp1_Lightskinlowtempnaturalh_8!D2 -> 32 | D10: =Exp1_Lightskinlowtempnaturalh_8!D3 -> 29 | F10: =Exp1_Lightskinlowtempnaturalh_8!D4 -> 27.25 | H10: =Exp1_Lightskinlowtempnaturalh_8!D5 -> 26.5 | J10: =Exp1_Lightskinlowtempnaturalh_8!D6 -> 25
A11: Dark skin emmisivity, low temp, natural home illumination | B11: =Exp1_Darkskinlowtempnaturalho_9!D2 -> 31.5 | D11: =Exp1_Darkskinlowtempnaturalho_9!D3 -> 28.5 | F11: =Exp1_Darkskinlowtempnaturalho_9!D4 -> 28.5 | H11: =Exp1_Darkskinlowtempnaturalho_9!D5 -> 27 | J11: =Exp1_Darkskinlowtempnaturalho_9!D6 -> 26.25
A12: Dark skin emissivity, low temp, artificial home illumination | B12: =Exp1_Darksknlowtepartificial_10!D2 -> 32.25 | D12: =Exp1_Darksknlowtepartificial_10!D3 -> 29.75 | F12: =Exp1_Darksknlowtepartificial_10!D4 -> 28.75 | H12: =Exp1_Darksknlowtepartificial_10!D5 -> 26.2 | J12: =Exp1_Darksknlowtepartificial_10!D6 -> 27
A13: Light skin emissivity, low temp, artificial home illumination | B13: =Exp1_lghtsknlowtempartificia_11!D2 -> 31.5 | D13: =Exp1_lghtsknlowtempartificia_11!D3 -> 29.25 | F13: =Exp1_lghtsknlowtempartificia_11!D4 -> 28.5 | H13: =Exp1_lghtsknlowtempartificia_11!D6 -> 27.5 | J13: =Exp1_lghtsknlowtempartificia_11!D6 -> 27.5
A15: Mean Temp reading for each distance (Metre) | B15: =AVERAGE(B3:B13) -> 32.945455 | D15: =AVERAGE(D3:D13) -> 30.686364 | F15: =AVERAGE(F3:F13) -> 29.590909 | H15: =AVERAGE(H3:H13) -> 28.563636 | J15: =AVERAGE(J3:J13) -> 28.013636

Sheet Exp1_ RobotShpMLXMeanvarianceSD
B1: Temp Readings at 1 Metre | C1: Temp Readings at 2 Metres | D1: Temp Readings at 3 Metres | E1: Temp Readings at 4 Metres | F1: Temp Readings at 5 Metres
B2: =Exp1_CategoriesofTempreadingRob!B3 -> 34.4 | C2: =Exp1_CategoriesofTempreadingRob!D3 -> 32.2 | D2: =Exp1_CategoriesofTempreadingRob!F3 -> 31 | E2: =Exp1_CategoriesofTempreadingRob!H3 -> 30 | F2: =Exp1_CategoriesofTempreadingRob!J3 -> 30.9
B3: =Exp1_CategoriesofTempreadingRob!B4 -> 34.5 | C3: =Exp1_CategoriesofTempreadingRob!D4 -> 32.9 | D3: =Exp1_CategoriesofTempreadingRob!F4 -> 32 | E3: =Exp1_CategoriesofTempreadingRob!H4 -> 31 | F3: =Exp1_CategoriesofTempreadingRob!J4 -> 31
B4: =Exp1_CategoriesofTempreadingRob!B5 -> 33.5 | C4: =Exp1_CategoriesofTempreadingRob!D5 -> 31 | D4: =Exp1_CategoriesofTempreadingRob!F5 -> 29 | E4: =Exp1_CategoriesofTempreadingRob!H5 -> 29 | F4: =Exp1_CategoriesofTempreadingRob!J5 -> 28
B5: =Exp1_CategoriesofTempreadingRob!B6 -> 33.5 | C5: =Exp1_CategoriesofTempreadingRob!D6 -> 31.75 | D5: =Exp1_CategoriesofTempreadingRob!F6 -> 30.25 | E5: =Exp1_CategoriesofTempreadingRob!H6 -> 29.25 | F5: =Exp1_CategoriesofTempreadingRob!J6 -> 29.75
B6: =Exp1_CategoriesofTempreadingRob!B7 -> 33.25 | C6: =Exp1_CategoriesofTempreadingRob!D7 -> 31 | D6: =Exp1_CategoriesofTempreadingRob!F7 -> 30.25 | E6: =Exp1_CategoriesofTempreadingRob!H7 -> 29.75 | F6: =Exp1_CategoriesofTempreadingRob!J7 -> 29.75
B7: =Exp1_CategoriesofTempreadingRob!B8 -> 33.5 | C7: =Exp1_CategoriesofTempreadingRob!D8 -> 31.7 | D7: =Exp1_CategoriesofTempreadingRob!F8 -> 30 | E7: =Exp1_CategoriesofTempreadingRob!H8 -> 29 | F7: =Exp1_CategoriesofTempreadingRob!J8 -> 29
B8: =Exp1_CategoriesofTempreadingRob!B9 -> 32.5 | C8: =Exp1_CategoriesofTempreadingRob!D9 -> 30.5 | D8: =Exp1_CategoriesofTempreadingRob!F9 -> 30 | E8: =Exp1_CategoriesofTempreadingRob!H9 -> 29 | F8: =Exp1_CategoriesofTempreadingRob!J9 -> 24
B9: =Exp1_CategoriesofTempreadingRob!B10 -> 32 | C9: =Exp1_CategoriesofTempreadingRob!D10 -> 29 | D9: =Exp1_CategoriesofTempreadingRob!F10 -> 27.25 | E9: =Exp1_CategoriesofTempreadingRob!H10 -> 26.5 | F9: =Exp1_CategoriesofTempreadingRob!J10 -> 25
B10: =Exp1_CategoriesofTempreadingRob!B11 -> 31.5 | C10: =Exp1_CategoriesofTempreadingRob!D11 -> 28.5 | D10: =Exp1_CategoriesofTempreadingRob!F11 -> 28.5 | E10: =Exp1_CategoriesofTempreadingRob!H11 -> 27 | F10: =Exp1_CategoriesofTempreadingRob!J11 -> 26.25
B11: =Exp1_CategoriesofTempreadingRob!B12 -> 32.25 | C11: =Exp1_CategoriesofTempreadingRob!D12 -> 29.75 | D11: =Exp1_CategoriesofTempreadingRob!F12 -> 28.75 | E11: =Exp1_CategoriesofTempreadingRob!H12 -> 26.2 | F11: =Exp1_CategoriesofTempreadingRob!J12 -> 27
B12: =Exp1_CategoriesofTempreadingRob!B13 -> 31.5 | C12: =Exp1_CategoriesofTempreadingRob!D13 -> 29.25 | D12: =Exp1_CategoriesofTempreadingRob!F13 -> 28.5 | E12: =Exp1_CategoriesofTempreadingRob!H13 -> 27.5 | F12: =Exp1_CategoriesofTempreadingRob!J13 -> 27.5
A14: Variance | B14: =_xlfn.VAR.S(Table11[Temp Readings at 1 Metre]) -> 1.1302273 | C14: =_xlfn.VAR.S(Table11[Temp Readings at 2 Metres]) -> 2.0145455 | D14: =_xlfn.VAR.S(Table11[Temp Readings at 3 Metres]) -> 1.7909091 | E14: =_xlfn.VAR.S(Table11[Temp Readings at 4 Metres]) -> 2.3870455 | F14: =_xlfn.VAR.S(Table11[Temp Readings at 5 Metres]) -> 5.3845455
A16: Standard Deviation (SD) | B16: =SQRT(B14) -> 1.0631215 | C16: =SQRT(C14) -> 1.4193468 | D16: =SQRT(D14) -> 1.3382485 | E16: =SQRT(E14) -> 1.5450066 | F16: =SQRT(F14) -> 2.3204623

Sheet Exp1_RSPROT10MeanvarianceSD
B1: Temp Readings at 1 Metre | C1: Temp Readings at 2 Metres | D1: Temp Readings at 3 Metres | E1: Temp Readings at 4 Metres | F1: Temp Readings at 5 Metres
B2: =Exp1_CategoriesofTempreadingbyR!B3 -> 32 | C2: =Exp1_CategoriesofTempreadingbyR!D3 -> 29 | D2: =Exp1_CategoriesofTempreadingbyR!F3 -> 21.5 | E2: =Exp1_CategoriesofTempreadingbyR!H3 -> 21.3 | F2: =Exp1_CategoriesofTempreadingbyR!J3 -> 21
B3: =Exp1_CategoriesofTempreadingbyR!B4 -> 33 | C3: =Exp1_CategoriesofTempreadingbyR!D4 -> 31 | D3: =Exp1_CategoriesofTempreadingbyR!F4 -> 29.5 | E3: =Exp1_CategoriesofTempreadingbyR!H4 -> 29.2 | F3: =Exp1_CategoriesofTempreadingbyR!J4 -> 28
B4: =Exp1_CategoriesofTempreadingbyR!B5 -> 31 | C4: =Exp1_CategoriesofTempreadingbyR!D5 -> 29 | D4: =Exp1_CategoriesofTempreadingbyR!F5 -> 26.5 | E4: =Exp1_CategoriesofTempreadingbyR!H5 -> 22 | F4: =Exp1_CategoriesofTempreadingbyR!J5 -> 21
B5: =Exp1_CategoriesofTempreadingbyR!B6 -> 30.1 | C5: =Exp1_CategoriesofTempreadingbyR!D6 -> 28.4 | D5: =Exp1_CategoriesofTempreadingbyR!F6 -> 28.7 | E5: =Exp1_CategoriesofTempreadingbyR!H6 -> 25.3 | F5: =Exp1_CategoriesofTempreadingbyR!J6 -> 25
B6: =Exp1_CategoriesofTempreadingbyR!B7 -> 30.4 | C6: =Exp1_CategoriesofTempreadingbyR!D7 -> 29.9 | D6: =Exp1_CategoriesofTempreadingbyR!F7 -> 28.7 | E6: =Exp1_CategoriesofTempreadingbyR!H7 -> 27.7 | F6: =Exp1_CategoriesofTempreadingbyR!J7 -> 25.7
B7: =Exp1_CategoriesofTempreadingbyR!B8 -> 30.3 | C7: =Exp1_CategoriesofTempreadingbyR!D8 -> 29.3 | D7: =Exp1_CategoriesofTempreadingbyR!F8 -> 28.8 | E7: =Exp1_CategoriesofTempreadingbyR!H8 -> 28.3 | F7: =Exp1_CategoriesofTempreadingbyR!J8 -> 28
B8: =Exp1_CategoriesofTempreadingbyR!B9 -> 29.8 | C8: =Exp1_CategoriesofTempreadingbyR!D9 -> 28.2 | D8: =Exp1_CategoriesofTempreadingbyR!F9 -> 25.9 | E8: =Exp1_CategoriesofTempreadingbyR!H9 -> 25.2 | F8: =Exp1_CategoriesofTempreadingbyR!J9 -> 20.2
B9: =Exp1_CategoriesofTempreadingbyR!B10 -> 31.6 | C9: =Exp1_CategoriesofTempreadingbyR!D10 -> 30 | D9: =Exp1_CategoriesofTempreadingbyR!F10 -> 29 | E9: =Exp1_CategoriesofTempreadingbyR!H10 -> 28.2 | F9: =Exp1_CategoriesofTempreadingbyR!J10 -> 27.5
B10: =Exp1_CategoriesofTempreadingbyR!B11 -> 30.9 | C10: =Exp1_CategoriesofTempreadingbyR!D11 -> 29.5 | D10: =Exp1_CategoriesofTempreadingbyR!F11 -> 28.8 | E10: =Exp1_CategoriesofTempreadingbyR!H11 -> 28.5 | F10: =Exp1_CategoriesofTempreadingbyR!J11 -> 28.5
B11: =Exp1_CategoriesofTempreadingbyR!B12 -> 30.4 | C11: =Exp1_CategoriesofTempreadingbyR!D12 -> 29.6 | D11: =Exp1_CategoriesofTempreadingbyR!F12 -> 28 | E11: =Exp1_CategoriesofTempreadingbyR!H12 -> 26.2 | F11: =Exp1_CategoriesofTempreadingbyR!J12 -> 26.5
B12: =Exp1_CategoriesofTempreadingbyR!B13 -> 30.1 | C12: =Exp1_CategoriesofTempreadingbyR!D13 -> 30 | D12: =Exp1_CategoriesofTempreadingbyR!F13 -> 28.8 | E12: =Exp1_CategoriesofTempreadingbyR!H13 -> 27.5 | F12: =Exp1_CategoriesofTempreadingbyR!J13 -> 27.4
A14: Variance | B14: =_xlfn.VAR.S(Table9[Temp Readings at 1 Metre]) -> 0.94618182 | C14: =_xlfn.VAR.S(Table9[Temp Readings at 2 Metres]) -> 0.63272727 | D14: =_xlfn.VAR.S(Table9[Temp Readings at 3 Metres]) -> 5.3747273 | E14: =_xlfn.VAR.S(Table9[Temp Readings at 4 Metres]) -> 6.9969091 | F14: =_xlfn.VAR.S(Table9[Temp Readings at 5 Metres]) -> 9.8727273
A16: Standard Deviation (SD) | B16: =SQRT(B14) -> 0.97271878 | C16: =SQRT(C14) -> 0.79544156 | D16: =SQRT(D14) -> 2.3183458 | E16: =SQRT(E14) -> 2.6451671 | F16: =SQRT(F14) -> 3.1420896

Sheet Exp1_PimoroniMLX90640MeanVrSD
B1: Temp Readings at 1 Metre | C1: Temp Readings at 2 Metres | D1: Temp Readings at 3 Metres | E1: Temp Readings at 4 Metres | F1: Temp Readings at 5 Metres
B2: =Exp1_CategoryofTempReadingfromP!B3 -> 34.4 | C2: =Exp1_CategoryofTempReadingfromP!D3 -> 32.2 | D2: =Exp1_CategoryofTempReadingfromP!F3 -> 31.5 | E2: =Exp1_CategoryofTempReadingfromP!H3 -> 30.5 | F2: =Exp1_CategoryofTempReadingfromP!J3 -> 30
B3: =Exp1_CategoryofTempReadingfromP!B4 -> 34.5 | C3: =Exp1_CategoryofTempReadingfromP!D4 -> 32.9 | D3: =Exp1_CategoryofTempReadingfromP!F4 -> 32.5 | E3: =Exp1_CategoryofTempReadingfromP!H4 -> 32.9 | F3: =Exp1_CategoryofTempReadingfromP!J4 -> 31.5
B4: =Exp1_CategoryofTempReadingfromP!B5 -> 33.5 | C4: =Exp1_CategoryofTempReadingfromP!D5 -> 31.5 | D4: =Exp1_CategoryofTempReadingfromP!F5 -> 29.2 | E4: =Exp1_CategoryofTempReadingfromP!H5 -> 29 | F4: =Exp1_CategoryofTempReadingfromP!J5 -> 28
B5: =Exp1_CategoryofTempReadingfromP!B6 -> 34.75 | C5: =Exp1_CategoryofTempReadingfromP!D6 -> 32.25 | D5: =Exp1_CategoryofTempReadingfromP!F6 -> 30.75 | E5: =Exp1_CategoryofTempReadingfromP!H6 -> 30.25 | F5: =Exp1_CategoryofTempReadingfromP!J6 -> 30
B6: =Exp1_CategoryofTempReadingfromP!B7 -> 34.5 | C6: =Exp1_CategoryofTempReadingfromP!D7 -> 31.75 | D6: =Exp1_CategoryofTempReadingfromP!F7 -> 30.5 | E6: =Exp1_CategoryofTempReadingfromP!H7 -> 30.25 | F6: =Exp1_CategoryofTempReadingfromP!J7 -> 29.75
B7: =Exp1_CategoryofTempReadingfromP!B8 -> 33.75 | C7: =Exp1_CategoryofTempReadingfromP!D8 -> 31.5 | D7: =Exp1_CategoryofTempReadingfromP!F8 -> 30.2 | E7: =Exp1_CategoryofTempReadingfromP!H8 -> 29.5 | F7: =Exp1_CategoryofTempReadingfromP!J8 -> 28.5
B8: =Exp1_CategoryofTempReadingfromP!B9 -> 32.5 | C8: =Exp1_CategoryofTempReadingfromP!D9 -> 30.75 | D8: =Exp1_CategoryofTempReadingfromP!F9 -> 29.7 | E8: =Exp1_CategoryofTempReadingfromP!H9 -> 28.75 | F8: =Exp1_CategoryofTempReadingfromP!J9 -> 24.1
B9: =Exp1_CategoryofTempReadingfromP!B10 -> 32 | C9: =Exp1_CategoryofTempReadingfromP!D10 -> 28.75 | D9: =Exp1_CategoryofTempReadingfromP!F10 -> 27.8 | E9: =Exp1_CategoryofTempReadingfromP!H10 -> 26.5 | F9: =Exp1_CategoryofTempReadingfromP!J10 -> 25.2
B10: =Exp1_CategoryofTempReadingfromP!B11 -> 32.75 | C10: =Exp1_CategoryofTempReadingfromP!D11 -> 29.25 | D10: =Exp1_CategoryofTempReadingfromP!F11 -> 28.25 | E10: =Exp1_CategoryofTempReadingfromP!H11 -> 27.25 | F10: =Exp1_CategoryofTempReadingfromP!J11 -> 27
B11: =Exp1_CategoryofTempReadingfromP!B12 -> 32.5 | C11: =Exp1_CategoryofTempReadingfromP!D12 -> 29.5 | D11: =Exp1_CategoryofTempReadingfromP!F12 -> 28.75 | E11: =Exp1_CategoryofTempReadingfromP!H12 -> 27.75 | F11: =Exp1_CategoryofTempReadingfromP!J12 -> 26.75
B12: =Exp1_CategoryofTempReadingfromP!B13 -> 32.2 | C12: =Exp1_CategoryofTempReadingfromP!D13 -> 30.5 | D12: =Exp1_CategoryofTempReadingfromP!F13 -> 29.75 | E12: =Exp1_CategoryofTempReadingfromP!H13 -> 28.75 | F12: =Exp1_CategoryofTempReadingfromP!J13 -> 28.25
A14: Variance | B14: =_xlfn.VAR.S(Table7[Temp Readings at 1 Metre]) -> 1.0817273 | C14: =_xlfn.VAR.S(Table7[Temp Readings at 2 Metres]) -> 1.8360455 | D14: =_xlfn.VAR.S(Table7[Temp Readings at 3 Metres]) -> 1.95 | E14: =_xlfn.VAR.S(Table7[Temp Readings at 4 Metres]) -> 3.1311364 | F14: =_xlfn.VAR.S(Table7[Temp Readings at 5 Metres]) -> 4.9137273
A16: Standard Deviation (SD) | B16: =SQRT(B14) -> 1.0400612 | C16: =SQRT(C14) -> 1.3550075 | D16: =SQRT(D14) -> 1.396424 | E16: =SQRT(E14) -> 1.7695017 | F16: =SQRT(F14) -> 2.2166929

Sheet Exp1_averageforeachthermalcamra
A1: Distance | B1: Pimoroni MLX90640 | C1: RS PRO T-10 | D1: Robotshop MLX90640
A2: 1 Metre | B2: =Exp1_CategoryofTempReadingfromP!B14 -> 33.395455 | C2: =Exp1_CategoriesofTempreadingbyR!B14 -> 30.872727 | D2: =Exp1_CategoriesofTempreadingRob!B15 -> 32.945455
A3: 2 Metres | B3: =Exp1_CategoryofTempReadingfromP!D14 -> 30.986364 | C3: =Exp1_CategoriesofTempreadingbyR!D14 -> 29.445455 | D3: =Exp1_CategoriesofTempreadingRob!D15 -> 30.686364
A4: 3 Metres | B4: =Exp1_CategoryofTempReadingfromP!F14 -> 29.9 | C4: =Exp1_CategoriesofTempreadingbyR!F14 -> 27.654545 | D4: =Exp1_CategoriesofTempreadingRob!F15 -> 29.590909
A5: 4 Metres | B5: =Exp1_CategoryofTempReadingfromP!H14 -> 29.218182 | C5: =Exp1_CategoriesofTempreadingbyR!H14 -> 26.309091 | D5: =Exp1_CategoriesofTempreadingRob!H15 -> 28.563636
A6: 5 Metres | B6: =Exp1_CategoryofTempReadingfromP!J14 -> 28.095455 | C6: =Exp1_CategoriesofTempreadingbyR!J14 -> 25.345455 | D6: =Exp1_CategoriesofTempreadingRob!J15 -> 28.013636

Sheet Exp1_VarianceateachThermalCamer
A1: Variance at each Distance | B1: Pimoroni MLX90640 | C1: RS PRO T-10 | D1: Robotshop MLX90640
A2: 1 Metre | B2: =Exp1_PimoroniMLX90640MeanVrSD!B14 -> 1.0817273 | C2: =Exp1_RSPROT10MeanvarianceSD!B14 -> 0.94618182 | D2: ='Exp1_ RobotShpMLXMeanvarianceSD'!B14 -> 1.1302273
A3: 2 Metres | B3: =Exp1_PimoroniMLX90640MeanVrSD!C14 -> 1.8360455 | C3: =Exp1_RSPROT10MeanvarianceSD!C14 -> 0.63272727 | D3: ='Exp1_ RobotShpMLXMeanvarianceSD'!C14 -> 2.0145455
A4: 3 Metres | B4: =Exp1_PimoroniMLX90640MeanVrSD!D14 -> 1.95 | C4: =Exp1_RSPROT10MeanvarianceSD!D14 -> 5.3747273 | D4: ='Exp1_ RobotShpMLXMeanvarianceSD'!D14 -> 1.7909091
A5: 4 Metres | B5: =Exp1_PimoroniMLX90640MeanVrSD!E14 -> 3.1311364 | C5: =Exp1_RSPROT10MeanvarianceSD!E14 -> 6.9969091 | D5: ='Exp1_ RobotShpMLXMeanvarianceSD'!E14 -> 2.3870455
A6: 5 Metres | B6: =Exp1_PimoroniMLX90640MeanVrSD!F14 -> 4.9137273 | C6: =Exp1_RSPROT10MeanvarianceSD!F14 -> 9.8727273 | D6: ='Exp1_ RobotShpMLXMeanvarianceSD'!F14 -> 5.3845455

Sheet Exp1_SDforeachThermalCamera
A1: SD at each Distance | B1: Pimoroni MLX90640 | C1: RS PRO T-10 | D1: Robotshop MLX90640
A2: 1 Metre | B2: =Exp1_PimoroniMLX90640MeanVrSD!B16 -> 1.0400612 | C2: =Exp1_RSPROT10MeanvarianceSD!B16 -> 0.97271878 | D2: ='Exp1_ RobotShpMLXMeanvarianceSD'!B16 -> 1.0631215
A3: 2 Metres | B3: =Exp1_PimoroniMLX90640MeanVrSD!C16 -> 1.3550075 | C3: =Exp1_RSPROT10MeanvarianceSD!C16 -> 0.79544156 | D3: ='Exp1_ RobotShpMLXMeanvarianceSD'!C16 -> 1.4193468
A4: 3 Metres | B4: =Exp1_PimoroniMLX90640MeanVrSD!D16 -> 1.396424 | C4: =Exp1_RSPROT10MeanvarianceSD!D16 -> 2.3183458 | D4: ='Exp1_ RobotShpMLXMeanvarianceSD'!D16 -> 1.3382485
A5: 4 Metres | B5: =Exp1_PimoroniMLX90640MeanVrSD!E16 -> 1.7695017 | C5: =Exp1_RSPROT10MeanvarianceSD!E16 -> 2.6451671 | D5: ='Exp1_ RobotShpMLXMeanvarianceSD'!E16 -> 1.5450066
A6: 5 Metres | B6: =Exp1_PimoroniMLX90640MeanVrSD!F16 -> 2.2166929 | C6: =Exp1_RSPROT10MeanvarianceSD!F16 -> 3.1420896 | D6: ='Exp1_ RobotShpMLXMeanvarianceSD'!F16 -> 2.3204623

Sheet Exp1_Average_SD
A2: Distance | B2: Pimoroni MLX90640 | C2: Pimoroni MLX906402 | E2: Distance | F2: RS PRO T-10 | G2: RS PRO T-102 | I2: Distance | J2: Robotshop MLX90640 | K2: Robotshop MLX906402
A3: =Exp1_averageforeachthermalcamra!A2 -> 1 Metre | B3: =Exp1_averageforeachthermalcamra!B2 -> 33.395455 | C3: =Exp1_SDforeachThermalCamera!B2 -> 1.0400612 | E3: 1 Metre | F3: =Exp1_averageforeachthermalcamra!C2 -> 30.872727 | G3: =Exp1_SDforeachThermalCamera!C2 -> 0.97271878 | I3: 1 Metre | J3: =Exp1_averageforeachthermalcamra!D2 -> 32.945455 | K3: =Exp1_SDforeachThermalCamera!D2 -> 1.0631215
A4: =Exp1_averageforeachthermalcamra!A3 -> 2 Metres | B4: =Exp1_averageforeachthermalcamra!B3 -> 30.986364 | C4: =Exp1_SDforeachThermalCamera!B3 -> 1.3550075 | E4: 2 Metres | F4: =Exp1_averageforeachthermalcamra!C3 -> 29.445455 | G4: =Exp1_SDforeachThermalCamera!C3 -> 0.79544156 | I4: 2 Metres | J4: =Exp1_averageforeachthermalcamra!D3 -> 30.686364 | K4: =Exp1_SDforeachThermalCamera!D3 -> 1.4193468
A5: =Exp1_averageforeachthermalcamra!A4 -> 3 Metres | B5: =Exp1_averageforeachthermalcamra!B4 -> 29.9 | C5: =Exp1_SDforeachThermalCamera!B4 -> 1.396424 | E5: 3 Metres | F5: =Exp1_averageforeachthermalcamra!C4 -> 27.654545 | G5: =Exp1_SDforeachThermalCamera!C4 -> 2.3183458 | I5: 3 Metres | J5: =Exp1_averageforeachthermalcamra!D4 -> 29.590909 | K5: =Exp1_SDforeachThermalCamera!D4 -> 1.3382485
A6: =Exp1_averageforeachthermalcamra!A5 -> 4 Metres | B6: =Exp1_averageforeachthermalcamra!B5 -> 29.218182 | C6: =Exp1_SDforeachThermalCamera!B5 -> 1.7695017 | E6: 4 Metres | F6: =Exp1_averageforeachthermalcamra!C5 -> 26.309091 | G6: =Exp1_SDforeachThermalCamera!C5 -> 2.6451671 | I6: 4 Metres | J6: =Exp1_averageforeachthermalcamra!D5 -> 28.563636 | K6: =Exp1_SDforeachThermalCamera!D5 -> 1.5450066
A7: =Exp1_averageforeachthermalcamra!A6 -> 5 Metres | B7: =Exp1_averageforeachthermalcamra!B6 -> 28.095455 | C7: =Exp1_SDforeachThermalCamera!B6 -> 2.2166929 | E7: 5 Metres | F7: =Exp1_averageforeachthermalcamra!C6 -> 25.345455 | G7: =Exp1_SDforeachThermalCamera!C6 -> 3.1420896 | I7: 5 Metres | J7: =Exp1_averageforeachthermalcamra!D6 -> 28.013636 | K7: =Exp1_SDforeachThermalCamera!D6 -> 2.3204623

Sheet Exp1_AV SD 
B1: Average Value | F1: Standard Deviation
A2: Distance | B2: Pimoroni MLX90640 | C2: RS PRO T-10 | D2: Robotshop MLX90640 | F2: Distance | G2: Pimoroni MLX906402 | H2: RS PRO T-102 | I2: Robotshop MLX906402
A3: =Exp1_averageforeachthermalcamra!A2 -> 1 Metre | B3: =Exp1_averageforeachthermalcamra!B2 -> 33.395455 | C3: =Exp1_averageforeachthermalcamra!C2 -> 30.872727 | D3: =Exp1_averageforeachthermalcamra!D2 -> 32.945455 | F3: 1 Metre | G3: =Exp1_SDforeachThermalCamera!B2 -> 1.0400612 | H3: =Exp1_SDforeachThermalCamera!C2 -> 0.97271878 | I3: =Exp1_SDforeachThermalCamera!D2 -> 1.0631215
A4: =Exp1_averageforeachthermalcamra!A3 -> 2 Metres | B4: =Exp1_averageforeachthermalcamra!B3 -> 30.986364 | C4: =Exp1_averageforeachthermalcamra!C3 -> 29.445455 | D4: =Exp1_averageforeachthermalcamra!D3 -> 30.686364 | F4: 2 Metres | G4: =Exp1_SDforeachThermalCamera!B3 -> 1.3550075 | H4: =Exp1_SDforeachThermalCamera!C3 -> 0.79544156 | I4: =Exp1_SDforeachThermalCamera!D3 -> 1.4193468
A5: =Exp1_averageforeachthermalcamra!A4 -> 3 Metres | B5: =Exp1_averageforeachthermalcamra!B4 -> 29.9 | C5: =Exp1_averageforeachthermalcamra!C4 -> 27.654545 | D5: =Exp1_averageforeachthermalcamra!D4 -> 29.590909 | F5: 3 Metres | G5: =Exp1_SDforeachThermalCamera!B4 -> 1.396424 | H5: =Exp1_SDforeachThermalCamera!C4 -> 2.3183458 | I5: =Exp1_SDforeachThermalCamera!D4 -> 1.3382485
A6: =Exp1_averageforeachthermalcamra!A5 -> 4 Metres | B6: =Exp1_averageforeachthermalcamra!B5 -> 29.218182 | C6: =Exp1_averageforeachthermalcamra!C5 -> 26.309091 | D6: =Exp1_averageforeachthermalcamra!D5 -> 28.563636 | F6: 4 Metres | G6: =Exp1_SDforeachThermalCamera!B5 -> 1.7695017 | H6: =Exp1_SDforeachThermalCamera!C5 -> 2.6451671 | I6: =Exp1_SDforeachThermalCamera!D5 -> 1.5450066
A7: =Exp1_averageforeachthermalcamra!A6 -> 5 Metres | B7: =Exp1_averageforeachthermalcamra!B6 -> 28.095455 | C7: =Exp1_averageforeachthermalcamra!C6 -> 25.345455 | D7: =Exp1_averageforeachthermalcamra!D6 -> 28.013636 | F7: 5 Metres | G7: =Exp1_SDforeachThermalCamera!B6 -> 2.2166929 | H7: =Exp1_SDforeachThermalCamera!C6 -> 3.1420896 | I7: =Exp1_SDforeachThermalCamera!D6 -> 2.3204623

Sheet 2Natutalillumination_light skin
A1: DATE/TIME | B1: Pimoroni MLX90640 (degree Celsius) | C1: RS PRO T-10 (degree Celsius) | D1: RobotShop MLX90640 (degree Celsius) | E1: Actual Temp (degree Celsius) | F1: DISTANCE (M) | G1: AMBIENT TEMP (degree Celsius)
A2: 09-09-24/12:00 | B2: 30.1 | C2: 29.7 | D2: 30 | E2: 36.5 | F2: 1 | G2: 16.5
A3: 09-09-24/12:01 | B3: 25.1 | C3: 29 | D3: 24.9 | E3: 36.5 | F3: 2 | G3: 16.5
A4: 09-09-24/12:02 | B4: 23 | C4: 24 | D4: 23 | E4: 36.5 | F4: 3 | G4: 16.5
A5: 09-09-24/12:03 | B5: 22 | C5: 24 | D5: 21 | E5: 36.5 | F5: 4 | G5: 16.5
A6: 09-09-24/12:04 | B6: 21 | C6: 24 | D6: 21 | E6: 36.5 | F6: 5 | G6: 16.5
A9: Average | B9: =AVERAGE(B2:B6) -> 24.24 | C9: =AVERAGE(C2:C6) -> 26.14 | D9: =AVERAGE(D2:D6) -> 23.98
B13: Natutal_illumination_light skin

Sheet 2NauralIllumination_dark_skinwg
A1: DATE/TIME | B1: Pimoroni MLX90640 (degree Celsius) | C1: RS PRO T-10 (degree Celsius) | D1: RobotShop MLX90640 (degree Celsius) | E1: Actual Temp (degree Celsius) | F1: DISTANCE (M) | G1: AMBIENT TEMP (degree Celsius)
A2: 09-09-24/12:15 | B2: 29 | C2: 29.3 | D2: 29.5 | E2: 35.7 | F2: 1 | G2: 16
A3: 09-09-24/12:16 | B3: 24.5 | C3: 29 | D3: 25.75 | E3: 35.7 | F3: 2 | G3: 16
A4: 09-09-24/12:17 | B4: 23.5 | C4: 27.8 | D4: 24 | E4: 35.7 | F4: 3 | G4: 16
A5: 09-09-24/12:18 | B5: 22 | C5: 27.8 | D5: 24 | E5: 35.7 | F5: 4 | G5: 16
A6: 09-09-24/12:19 | B6: 21.5 | C6: 25 | D6: 22.5 | E6: 35.7 | F6: 5 | G6: 16
A9: Average | B9: =AVERAGE(B2:B6) -> 24.1 | C9: =AVERAGE(C2:C6) -> 27.78 | D9: =AVERAGE(D2:D6) -> 25.15
B13: Naural Illumination dark skin with eye glasses on

Sheet 2NauralIllumination_darkskinwtg
A1: DATE/TIME | B1: Pimoroni MLX90640 (degree Celsius) | C1: RS PRO T-10 (degree Celsius) | D1: RobotShop MLX90640 (degree Celsius) | E1: Actual Temp (degree Celsius) | F1: DISTANCE (M) | G1: AMBIENT TEMP (degree Celsius)
A2: 09-09-24/12:15 | B2: 29.7 | C2: 30 | D2: 31.5 | E2: 35.7 | F2: 1 | G2: 16
A3: 09-09-24/12:16 | B3: 25.7 | C3: 29.8 | D3: 27 | E3: 35.7 | F3: 2 | G3: 16
A4: 09-09-24/12:17 | B4: 23.8 | C4: 28.9 | D4: 24.3 | E4: 35.7 | F4: 3 | G4: 16
A5: 09-09-24/12:18 | B5: 21.8 | C5: 27.3 | D5: 22.5 | E5: 35.7 | F5: 4 | G5: 16
A6: 09-09-24/12:19 | B6: 21.5 | C6: 26.2 | D6: 22 | E6: 35.7 | F6: 5 | G6: 16
A9: Average | B9: =AVERAGE(B2:B6) -> 24.5 | C9: =AVERAGE(C2:C6) -> 28.44 | D9: =AVERAGE(D2:D6) -> 25.46
B14: Natural Illumination dark skin without Glasses

Sheet 2ArtificialIllumination_Light_s
A1: DATE/TIME | B1: Pimoroni MLX90640 (degree Celsius) | C1: RS PRO T-10 (degree Celsius) | D1: RobotShop MLX90640 (degree Celsius) | E1: Actual Temp (degree Celsius) | F1: DISTANCE (M) | G1: AMBIENT TEMP (degree Celsius)
A2: 09-09-24/12:28 | B2: 28.1 | C2: 30.4 | D2: 29 | E2: 36 | F2: 1 | G2: 16.5
A3: 09-09-24/12:29 | B3: 24.5 | C3: 29.2 | D3: 25.6 | E3: 36 | F3: 2 | G3: 16.5
A4: 09-09-24/12:30 | B4: 23.5 | C4: 27.5 | D4: 24 | E4: 36 | F4: 3 | G4: 16.5
A5: 09-09-24/12:31 | B5: 22 | C5: 26.2 | D5: 22.5 | E5: 36 | F5: 4 | G5: 16.5
A6: 09-09-24/12:32 | B6: 22 | C6: 24.2 | D6: 22 | E6: 36 | F6: 5 | G6: 16.5
A9: Average | B9: =AVERAGE(B2:B6) -> 24.02 | C9: =AVERAGE(C2:C6) -> 27.5 | D9: =AVERAGE(D2:D6) -> 24.62
B15: Artificial Illumination Light skin

Sheet 2artificialilluminatn_dksknwG
A1: DATE/TIME | B1: Pimoroni MLX90640 (degree Celsius) | C1: RS PRO T-10 (degree Celsius) | D1: RobotShop MLX90640 (degree Celsius) | E1: Actual Temp (degree Celsius) | F1: DISTANCE (M) | G1: AMBIENT TEMP (degree Celsius)
A2: 09-09-24/13:35 | B2: 29 | C2: 29.7 | D2: 30 | E2: 36 | F2: 1 | G2: 17
A3: 09-09-24/13:37 | B3: 26.5 | C3: 28.7 | D3: 26.8 | E3: 36 | F3: 2 | G3: 17
A4: 09-09-24/13:39 | B4: 24 | C4: 27.9 | D4: 24.5 | E4: 36 | F4: 3 | G4: 17
A5: 09-09-24/13:41 | B5: 23 | C5: 26.3 | D5: 24.4 | E5: 36 | F5: 4 | G5: 17
A6: 09-09-24/13:43 | B6: 22.8 | C6: 26.1 | D6: 23 | E6: 36 | F6: 5 | G6: 17
A9: average | B9: =AVERAGE(B2:B6) -> 25.06 | C9: =AVERAGE(C2:C6) -> 27.74 | D9: =AVERAGE(D2:D6) -> 25.74
B14: Artificial illumination Dark skin with eye glass

Sheet 2Artificialillumination_Dark_sk
A1: DATE/TIME | B1: Pimoroni MLX90640 (degree Celsius) | C1: RS PRO T-10 (degree Celsius) | D1: RobotShop MLX90640 (degree Celsius) | E1: Actual Temp (degree Celsius) | F1: DISTANCE (M) | G1: AMBIENT TEMP (degree Celsius)
A2: 09-09-24/12:35 | B2: 29.8 | C2: 29.9 | D2: 31 | E2: 36 | F2: 1 | G2: 36
A3: 09-09-24/12:37 | B3: 26.3 | C3: 29.2 | D3: 27.5 | E3: 36 | F3: 2 | G3: 36
A4: 09-09-24/12:39 | B4: 24.5 | C4: 28.4 | D4: 25 | E4: 36 | F4: 3 | G4: 36
A5: 09-09-24/12:41 | B5: 23 | C5: 27.5 | D5: 24.5 | E5: 36 | F5: 4 | G5: 36
A6: 09-09-24/12:43 | B6: 22.5 | C6: 26.4 | D6: 23.8 | E6: 36 | F6: 5 | G6: 36
A9: Average | B9: =AVERAGE(B2:B6) -> 25.22 | C9: =AVERAGE(C2:C6) -> 28.28 | D9: =AVERAGE(D2:D6) -> 26.36
B16: Artificial illumination Dark skin without eye glass

Sheet 2NatutalIlluminatn _ltsknwg
A1: DATE/TIME | B1: Pimoroni MLX90640 (degree Celsius) | C1: RS PRO T-10 (degree Celsius) | D1: RobotShop MLX90640 (degree Celsius) | E1: Actual Temp (degree Celsius) | F1: DISTANCE (M) | G1: AMBIENT TEMP (degree Celsius)
A2: 09-09-24/13:55 | B2: 30 | C2: 30.4 | D2: 30.5 | E2: 35.7 | F2: 1 | G2: 16.5
A3: 09-09-24/13:56 | B3: 26.5 | C3: 28.6 | D3: 26 | E3: 35.7 | F3: 2 | G3: 16.5
A4: 09-09-24/13:57 | B4: 24 | C4: 26.2 | D4: 24.5 | E4: 35.7 | F4: 3 | G4: 16.5
A5: 09-09-24/13:58 | B5: 22.5 | C5: 24.6 | D5: 23 | E5: 35.7 | F5: 4 | G5: 16.5
A6: 09-09-24/13:59 | B6: 21.8 | C6: 22.9 | D6: 22.5 | E6: 35.7 | F6: 5 | G6: 16.5
A9: Average | B9: =AVERAGE(B2:B6) -> 24.96 | C9: =AVERAGE(C2:C6) -> 26.54 | D9: =AVERAGE(D2:D6) -> 25.3
B12: Natutal Illumination light skin with Glasses

Sheet 2NatutalIlluminatn _ltsknwhgl
A1: DATE/TIME | B1: Pimoroni MLX90640 (degree Celsius) | C1: RS PRO T-10 (degree Celsius) | D1: RobotShop MLX90640 (degree Celsius) | E1: Actual Temp (degree Celsius) | F1: DISTANCE (M) | G1: AMBIENT TEMP (degree Celsius)
A2: 09-09-24/13:55 | B2: 30.5 | C2: 30.3 | D2: 31.2 | E2: 35.7 | F2: 1 | G2: 16.5
A3: 09-09-24/13:56 | B3: 25.5 | C3: 28.9 | D3: 26 | E3: 35.7 | F3: 2 | G3: 16.5
A4: 09-09-24/13:57 | B4: 24.3 | C4: 27.5 | D4: 25 | E4: 35.7 | F4: 3 | G4: 16.5
A5: 09-09-24/13:58 | B5: 22.25 | C5: 26.3 | D5: 24 | E5: 35.7 | F5: 4 | G5: 16.5
A6: 09-09-24/13:59 | B6: 21.8 | C6: 23.6 | D6: 23.3 | E6: 35.7 | F6: 5 | G6: 16.5
A9: Avarage | B9: =AVERAGE(B2:B6) -> 24.87 | C9: =AVERAGE(C2:C6) -> 27.32 | D9: =AVERAGE(D2:D6) -> 25.9
B14: Natutal illumination light skin without glasses

Sheet 2artificialillumintn_litsknwg
A1: DATE/TIME | B1: Pimoroni MLX90640 (degree Celsius) | C1: RS PRO T-10 (degree Celsius) | D1: RobotShop MLX90640 (degree Celsius) | E1: Actual Temp (degree Celsius) | F1: DISTANCE (M) | G1: AMBIENT TEMP (degree Celsius)
A2: 09-09-24/14:00 | B2: 28.8 | C2: 30.5 | D2: 29.5 | E2: 37.5 | F2: 1 | G2: 16.5
A3: 09-09-24/14:02 | B3: 25.5 | C3: 28.5 | D3: 26.3 | E3: 37.5 | F3: 2 | G3: 16.5
A4: 09-09-24/14:04 | B4: 24.1 | C4: 28.1 | D4: 25 | E4: 37.5 | F4: 3 | G4: 16.5
A5: 09-09-24/14:06 | B5: 23.8 | C5: 27 | D5: 24.3 | E5: 37.5 | F5: 4 | G5: 17
A6: 09-09-24/14:08 | B6: 23.5 | C6: 26.1 | D6: 24 | E6: 37.5 | F6: 5 | G6: 17
A8: Average | B8: =AVERAGE(B2:B6) -> 25.14 | C8: =AVERAGE(C2:C6) -> 28.04 | D8: =AVERAGE(D2:D6) -> 25.82
B14: Artificail illumination light skin with glasses

Sheet 2artificialillumintn_litsknwhgl
A1: DATE/TIME | B1: Pimoroni MLX90640 (degree Celsius) | C1: RS PRO T-10 (degree Celsius) | D1: RobotShop MLX90640 (degree Celsius) | E1: Actual Temp (degree Celsius) | F1: DISTANCE (M) | G1: AMBIENT TEMP (degree Celsius)
A2: 09-09-24/14:00 | B2: 29.5 | C2: 30.8 | D2: 30.5 | E2: 37.5 | F2: 1 | G2: 16.5
A3: 09-09-24/14:02 | B3: 25.5 | C3: 28.9 | D3: 26.3 | E3: 37.5 | F3: 2 | G3: 16.5
A4: 09-09-24/14:04 | B4: 24.5 | C4: 28 | D4: 25.3 | E4: 37.5 | F4: 3 | G4: 16.5
A5: 09-09-24/14:06 | B5: 23.8 | C5: 27.5 | D5: 24.8 | E5: 37.5 | F5: 4 | G5: 17
A6: 09-09-24/14:08 | B6: 23 | C6: 26.5 | D6: 24 | E6: 37.5 | F6: 5 | G6: 17
A9: Average | B9: =AVERAGE(B2:B6) -> 25.26 | C9: =AVERAGE(C2:C6) -> 28.34 | D9: =AVERAGE(D2:D6) -> 26.18
B13: Artificial Illumination light skin without glasses

Sheet readingdistancePimoroniMLX9064
A1: Category of Temp reading from Pimoroni MLX90640 (degree Celsius) | B1: Temp Readings at 1 Metre | C1: Temp Readings at 2 Metres | D1: Temp Readings at 3 Metres | E1: Temp Readings at 4 Metres | F1: Temp Readings at 5 Metres
A2: Light skin emissivity under natural Illumination | B2: ='[1]Natutal_illumination_light skin'!B2 -> 30.1 | C2: ='[1]Natutal_illumination_light skin'!B3 -> 25.1 | D2: ='[1]Natutal_illumination_light skin'!B4 -> 23 | E2: ='[1]Natutal_illumination_light skin'!B5 -> 22 | F2: ='[1]Natutal_illumination_light skin'!B6 -> 21
A3: Dark skin emissivity under natural Illumination with eye glasses on | B3: =[1]Naural_Illumination_dark_skinwg!$B$2 -> 29 | C3: =[1]Naural_Illumination_dark_skinwg!$B$3 -> 24.5 | D3: =[1]Naural_Illumination_dark_skinwg!$B$4 -> 23.5 | E3: =[1]Naural_Illumination_dark_skinwg!$B$5 -> 22 | F3: =[1]Naural_Illumination_dark_skinwg!$B$6 -> 21.5
A4: Dark skin emissivity under natural Illumination without eye glasses on | B4: =[1]Naural_Illumination_darkskinwtg!$B$2 -> 29.7 | C4: =[1]Naural_Illumination_darkskinwtg!$B$3 -> 25.7 | D4: =[1]Naural_Illumination_darkskinwtg!$B$4 -> 23.8 | E4: =[1]Naural_Illumination_darkskinwtg!$B$5 -> 21.8 | F4: =[1]Naural_Illumination_darkskinwtg!$B$6 -> 21.5
A5: Light skin emissivity under artificial Illumination | B5: =[1]Artificial_Illumination_Light_s!B2 -> 28.1 | C5: =[1]Artificial_Illumination_Light_s!B3 -> 24.5 | D5: =[1]Artificial_Illumination_Light_s!B4 -> 23.5 | E5: =[1]Artificial_Illumination_Light_s!B6 -> 22 | F5: =[1]Artificial_Illumination_Light_s!B6 -> 22
A6: Dark skin emissivity under artificial Illumination with eyeglasses on | B6: =[1]artificial_illuminatn_dksknwG!B2 -> 29 | C6: =[1]artificial_illuminatn_dksknwG!B3 -> 26.5 | D6: =[1]artificial_illuminatn_dksknwG!B4 -> 24 | E6: =[1]artificial_illuminatn_dksknwG!B5 -> 23 | F6: =[1]artificial_illuminatn_dksknwG!B6 -> 22.8
A7: Dark skin emissivity under artificial l Illumination without eyeglasses on | B7: =[1]Artificial_illumination_Dark_sk!$B$2 -> 29.8 | C7: =[1]Artificial_illumination_Dark_sk!$B$3 -> 26.3 | D7: =[1]Artificial_illumination_Dark_sk!$B$4 -> 24.5 | E7: =[1]Artificial_illumination_Dark_sk!$B$5 -> 23 | F7: =[1]Artificial_illumination_Dark_sk!$B$6 -> 22.5
A8: Light skin emissivity under natural Illumination with eyeglasses on | B8: ='[1]Natutal_Illuminatn _ltsknwg'!B2 -> 30 | C8: ='[1]Natutal_Illuminatn _ltsknwg'!B3 -> 26.5 | D8: ='[1]Natutal_Illuminatn _ltsknwg'!B4 -> 24 | E8: ='[1]Natutal_Illuminatn _ltsknwg'!B5 -> 22.5 | F8: ='[1]Natutal_Illuminatn _ltsknwg'!B6 -> 21.8
A9: Light skin emissivity under natural Illumination without eye glasses on | B9: ='[1]Natutal_Illuminatn _ltsknwhgl'!B2 -> 30.5 | C9: ='[1]Natutal_Illuminatn _ltsknwhgl'!B3 -> 25.5 | D9: ='[1]Natutal_Illuminatn _ltsknwhgl'!B4 -> 24.3 | E9: ='[1]Natutal_Illuminatn _ltsknwhgl'!B5 -> 22.25 | F9: ='[1]Natutal_Illuminatn _ltsknwhgl'!B6 -> 21.8
A10: Light skin emissivity under artificial Illumination with eyeglasses on | B10: =[1]artificial_illumintn_litsknwg!B2 -> 28.8 | C10: =[1]artificial_illumintn_litsknwg!B3 -> 25.5 | D10: =[1]artificial_illumintn_litsknwg!B4 -> 24.1 | E10: =[1]artificial_illumintn_litsknwg!B5 -> 23.8 | F10: =[1]artificial_illumintn_litsknwg!B6 -> 23.5
A11: Light skin emissivity under artificial l Illumination without eyeglasses on | B11: =[1]artificial_illumintn_litsknwhgl!B2 -> 29.5 | C11: =[1]artificial_illumintn_litsknwhgl!B3 -> 25.5 | D11: =[1]artificial_illumintn_litsknwhgl!B4 -> 24.5 | E11: =[1]artificial_illumintn_litsknwhgl!B5 -> 23.8 | F11: =[1]artificial_illumintn_litsknwhgl!B6 -> 23
A13: Mean Temp reading for each distance (Metre) | B13: =AVERAGE(B2:B11) -> 29.45 | C13: =AVERAGE(C2:C11) -> 25.56 | D13: =AVERAGE(D2:D11) -> 23.92 | E13: =AVERAGE(E2:E11) -> 22.615 | F13: =AVERAGE(F2:F11) -> 22.14
A15: Variance | B15: =_xlfn.VAR.S(B2:B11) -> 0.51833333 | C15: =_xlfn.VAR.S(C2:C11) -> 0.53377778 | D15: =_xlfn.VAR.S(D2:D11) -> 0.23066667 | E15: =_xlfn.VAR.S(E2:E11) -> 0.56113889 | F15: =_xlfn.VAR.S(F2:F11) -> 0.61377778
A17: Standard Deviation | B17: =SQRT(B15) -> 0.7199537 | C17: =SQRT(C15) -> 0.73060097 | D17: =SQRT(D15) -> 0.4802777 | E17: =SQRT(E15) -> 0.74909204 | F17: =SQRT(F15) -> 0.78343971

Sheet readingdistanceRSPROT-10
A1: Category of Temp reading from RS PRO T-10 (Degree Celsius) | B1: Temp Readings at 1 Metre | C1: Temp Readings at 2 Metres | D1: Temp Readings at 3 Metres | E1: Temp Readings at 4 Metres | F1: Temp Readings at 5 Metres
A2: Light skin emissivity under natural Illumination | B2: ='[1]Natutal_illumination_light skin'!C2 -> 29.7 | C2: ='[1]Natutal_illumination_light skin'!C3 -> 29 | D2: ='[1]Natutal_illumination_light skin'!C4 -> 24 | E2: ='[1]Natutal_illumination_light skin'!C5 -> 24 | F2: ='[1]Natutal_illumination_light skin'!C6 -> 24
A3: Dark skin emissivity under natural Illumination with eye glasses on | B3: =[1]Naural_Illumination_dark_skinwg!$C$2 -> 29.3 | C3: =[1]Naural_Illumination_dark_skinwg!$C$3 -> 29 | D3: =[1]Naural_Illumination_dark_skinwg!$C$4 -> 27.8 | E3: =[1]Naural_Illumination_dark_skinwg!$C$5 -> 27.8 | F3: =[1]Naural_Illumination_dark_skinwg!$C$6 -> 25
A4: Dark skin emissivity under natural Illumination without eye glasses on | B4: =[1]Naural_Illumination_darkskinwtg!$C$2 -> 30 | C4: =[1]Naural_Illumination_darkskinwtg!$C$3 -> 29.8 | D4: =[1]Naural_Illumination_darkskinwtg!$C$4 -> 28.9 | E4: =[1]Naural_Illumination_darkskinwtg!$C$5 -> 27.3 | F4: =[1]Naural_Illumination_darkskinwtg!$C$6 -> 26.2
A5: Light skin emissivity under artificial Illumination | B5: =[1]Artificial_Illumination_Light_s!C2 -> 30.4 | C5: =[1]Artificial_Illumination_Light_s!C3 -> 29.2 | D5: =[1]Artificial_Illumination_Light_s!C4 -> 27.5 | E5: =[1]Artificial_Illumination_Light_s!C5 -> 26.2 | F5: =[1]Artificial_Illumination_Light_s!C6 -> 24.2
A6: Dark skin emissivity under artificial Illumination with eyeglasses on | B6: =[1]artificial_illuminatn_dksknwG!C2 -> 29.7 | C6: =[1]artificial_illuminatn_dksknwG!C3 -> 28.7 | D6: =[1]artificial_illuminatn_dksknwG!C4 -> 27.9 | E6: =[1]artificial_illuminatn_dksknwG!C5 -> 26.3 | F6: =[1]artificial_illuminatn_dksknwG!C6 -> 26.1
A7: Dark skin emissivity under artificial l Illumination without eyeglasses on | B7: =[1]Artificial_illumination_Dark_sk!$C$2 -> 29.9 | C7: =[1]Artificial_illumination_Dark_sk!$C$3 -> 29.2 | D7: =[1]Artificial_illumination_Dark_sk!$C$4 -> 28.4 | E7: =[1]Artificial_illumination_Dark_sk!$C$5 -> 27.5 | F7: =[1]Artificial_illumination_Dark_sk!$C$6 -> 26.4
A8: Light skin emissivity under natural Illumination with eyeglasses on | B8: ='[1]Natutal_Illuminatn _ltsknwg'!C2 -> 30.4 | C8: ='[1]Natutal_Illuminatn _ltsknwg'!C3 -> 28.6 | D8: ='[1]Natutal_Illuminatn _ltsknwg'!C4 -> 26.2 | E8: ='[1]Natutal_Illuminatn _ltsknwg'!C5 -> 24.6 | F8: ='[1]Natutal_Illuminatn _ltsknwg'!C6 -> 22.9
A9: Light skin emissivity under natural Illumination without eye glasses on | B9: ='[1]Natutal_Illuminatn _ltsknwhgl'!C2 -> 30.3 | C9: ='[1]Natutal_Illuminatn _ltsknwhgl'!C3 -> 28.9 | D9: ='[1]Natutal_Illuminatn _ltsknwhgl'!C4 -> 27.5 | E9: ='[1]Natutal_Illuminatn _ltsknwhgl'!C5 -> 26.3 | F9: ='[1]Natutal_Illuminatn _ltsknwhgl'!C6 -> 23.6
A10: Light skin emissivity under artificial Illumination with eyeglasses on | B10: =[1]artificial_illumintn_litsknwg!C2 -> 30.5 | C10: =[1]artificial_illumintn_litsknwg!C3 -> 28.5 | D10: =[1]artificial_illumintn_litsknwg!C4 -> 28.1 | E10: =[1]artificial_illumintn_litsknwg!C5 -> 27 | F10: =[1]artificial_illumintn_litsknwg!B6 -> 23.5
A11: Light skin emissivity under artificial l Illumination without eyeglasses on | B11: =[1]artificial_illumintn_litsknwhgl!C2 -> 30.8 | C11: =[1]artificial_illumintn_litsknwhgl!C3 -> 28.9 | D11: =[1]artificial_illumintn_litsknwhgl!C4 -> 28 | E11: =[1]artificial_illumintn_litsknwhgl!C5 -> 27.5 | F11: =[1]artificial_illumintn_litsknwhgl!C6 -> 26.5
A13: Mean Temp reading for each distance (Metre) | B13: =AVERAGE(B2:B11) -> 30.1 | C13: =AVERAGE(C2:C11) -> 28.98 | D13: =AVERAGE(D2:D11) -> 27.43 | E13: =AVERAGE(E2:E11) -> 26.45 | F13: =AVERAGE(F2:F11) -> 24.84
A15: Variance | B15: =_xlfn.VAR.S(B2:B11) -> 0.20888889 | C15: =_xlfn.VAR.S(C2:C11) -> 0.13733333 | D15: =_xlfn.VAR.S(D2:D11) -> 1.9467778 | E15: =_xlfn.VAR.S(E2:E11) -> 1.6205556 | F15: =_xlfn.VAR.S(F2:F11) -> 1.8737778
A17: Standard Deviation | B17: =SQRT(B15) -> 0.45704364 | C17: =SQRT(C15) -> 0.37058512 | D17: =SQRT(D15) -> 1.3952698 | E17: =SQRT(E15) -> 1.2730104 | F17: =SQRT(F15) -> 1.36886

Sheet readingdistnceRobotshopMLX90640
A1: Category of Temp reading from Robotshop MLX90640 (Degree Celsius) | B1: Temp Readings at 1 Metre | C1: Temp Readings at 2 Metres | D1: Temp Readings at 3 Metres | E1: Temp Readings at 4 Metres | F1: Temp Readings at 5 Metres
A2: Light skin emissivity under natural Illumination | B2: ='[1]Natutal_illumination_light skin'!D2 -> 30 | C2: ='[1]Natutal_illumination_light skin'!D3 -> 24.9 | D2: ='[1]Natutal_illumination_light skin'!D4 -> 23 | E2: ='[1]Natutal_illumination_light skin'!D5 -> 21 | F2: ='[1]Natutal_illumination_light skin'!D6 -> 21
A3: Dark skin emissivity under natural Illumination with eye glasses on | B3: =[1]Naural_Illumination_dark_skinwg!$D$2 -> 29.5 | C3: =[1]Naural_Illumination_dark_skinwg!$D$3 -> 25.75 | D3: =[1]Naural_Illumination_dark_skinwg!$D$4 -> 24 | E3: =[1]Naural_Illumination_dark_skinwg!$D$5 -> 24 | F3: =[1]Naural_Illumination_dark_skinwg!$D$6 -> 22.5
A4: Dark skin emissivity under natural Illumination without eye glasses on | B4: =[1]Naural_Illumination_darkskinwtg!$D$2 -> 31.5 | C4: =[1]Naural_Illumination_darkskinwtg!$D$3 -> 27 | D4: =[1]Naural_Illumination_darkskinwtg!$D$4 -> 24.3 | E4: =[1]Naural_Illumination_darkskinwtg!$D$5 -> 22.5 | F4: =[1]Naural_Illumination_darkskinwtg!$D$6 -> 22
A5: Light skin emissivity under artificial Illumination | B5: =[1]Artificial_Illumination_Light_s!D2 -> 29 | C5: =[1]Artificial_Illumination_Light_s!D3 -> 25.6 | D5: =[1]Artificial_Illumination_Light_s!D4 -> 24 | E5: =[1]Artificial_Illumination_Light_s!D5 -> 22.5 | F5: =[1]Artificial_Illumination_Light_s!D6 -> 22
A6: Dark skin emissivity under artificial Illumination with eyeglasses on | B6: =[1]artificial_illuminatn_dksknwG!D2 -> 30 | C6: =[1]artificial_illuminatn_dksknwG!D3 -> 26.8 | D6: =[1]artificial_illuminatn_dksknwG!D4 -> 24.5 | E6: =[1]artificial_illuminatn_dksknwG!D5 -> 24.4 | F6: =[1]artificial_illuminatn_dksknwG!D6 -> 23
A7: Dark skin emissivity under artificial l Illumination without eyeglasses on | B7: =[1]Artificial_illumination_Dark_sk!$D$2 -> 31 | C7: =[1]Artificial_illumination_Dark_sk!$D$3 -> 27.5 | D7: =[1]Artificial_illumination_Dark_sk!$D$4 -> 25 | E7: =[1]Artificial_illumination_Dark_sk!$D$5 -> 24.5 | F7: =[1]Artificial_illumination_Dark_sk!$D$6 -> 23.8
A8: Light skin emissivity under natural Illumination with eyeglasses on | B8: ='[1]Natutal_Illuminatn _ltsknwg'!D2 -> 30.5 | C8: ='[1]Natutal_Illuminatn _ltsknwg'!D3 -> 26 | D8: ='[1]Natutal_Illuminatn _ltsknwg'!D4 -> 24.5 | E8: ='[1]Natutal_Illuminatn _ltsknwg'!D5 -> 23 | F8: ='[1]Natutal_Illuminatn _ltsknwg'!D6 -> 22.5
A9: Light skin emissivity under natural Illumination without eye glasses on | B9: ='[1]Natutal_Illuminatn _ltsknwhgl'!D2 -> 31.2 | C9: ='[1]Natutal_Illuminatn _ltsknwhgl'!D3 -> 26 | D9: ='[1]Natutal_Illuminatn _ltsknwhgl'!D4 -> 25 | E9: ='[1]Natutal_Illuminatn _ltsknwhgl'!D5 -> 24 | F9: ='[1]Natutal_Illuminatn _ltsknwhgl'!D6 -> 23.3
A10: Light skin emissivity under artificial Illumination with eyeglasses on | B10: =[1]artificial_illumintn_litsknwg!D2 -> 29.5 | C10: =[1]artificial_illumintn_litsknwg!D3 -> 26.3 | D10: =[1]artificial_illumintn_litsknwg!D4 -> 25 | E10: =[1]artificial_illumintn_litsknwg!D5 -> 24.3 | F10: =[1]artificial_illumintn_litsknwg!D6 -> 24
A11: Light skin emissivity under artificial l Illumination without eyeglasses on | B11: =[1]artificial_illumintn_litsknwhgl!D2 -> 30.5 | C11: =[1]artificial_illumintn_litsknwhgl!D3 -> 26.3 | D11: =[1]artificial_illumintn_litsknwhgl!D4 -> 25.3 | E11: =[1]artificial_illumintn_litsknwhgl!D5 -> 24.8 | F11: =[1]artificial_illumintn_litsknwhgl!D6 -> 24
A13: Mean Temp reading for each distance (Metre) | B13: =AVERAGE(B2:B11) -> 30.27 | C13: =AVERAGE(C2:C11) -> 26.215 | D13: =AVERAGE(D2:D11) -> 24.46 | E13: =AVERAGE(E2:E11) -> 23.5 | F13: =AVERAGE(F2:F11) -> 22.81
