Workbook

Sheet Raw_Data
E1: Camera 1 – PIMORONI | J1: camera2 - ROBOT SHOP | O1: Camera 3 - RS PRO
A2: ID | B2: glasses | C2: body temp | D2: ambient temp | E2: 1M | F2: 2M | G2: 3M | H2: 4M | I2: 5M | J2: 1M | K2: 2M | L2: 3M | M2: 4M | N2: 5M | O2: 1M | P2: 2M | Q2: 3M | R2: 4M | S2: 5M
A3: 1 | B3: N | C3: 36.8 | D3: 16 | E3: 30.3 | F3: 25.5 | G3: 23 | H3: 22.06 | I3: 21.5 | J3: 30.5 | K3: 26 | L3: 23.5 | M3: 22.5 | N3: 21 | O3: 29.5 | P3: 27 | Q3: 26 | R3: 23 | S3: 21.7
A4: 2 | B4: Y | C4: 36.8 | D4: 16 | E4: 30 | F4: 29.5 | G4: 26 | H4: 24.5 | I4: 22.5 | J4: 30.5 | K4: 28.5 | L4: 25.5 | M4: 22.5 | N4: 23 | O4: 30 | P4: 28.7 | Q4: 25.7 | R4: 23.5 | S4: 22.5
A5: 3 | B5: N | C5: 36.8 | D5: 16 | E5: 30.3 | F5: 30 | G5: 25.5 | H5: 23.5 | I5: 22 | J5: 30.8 | K5: 29 | L5: 25.3 | M5: 23 | N5: 23 | O5: 30 | P5: 28.5 | Q5: 26.5 | R5: 24.5 | S5: 22.5
A6: 4 | B6: Y | C6: 36.6 | D6: 16 | E6: 30.5 | F6: 27.9 | G6: 25.2 | H6: 23 | I6: 21.7 | J6: 31.2 | K6: 28.5 | L6: 25.4 | M6: 24 | N6: 22 | O6: 32 | P6: 30 | Q6: 26 | R6: 24 | S6: 22.5
A7: 5 | B7: N | C7: 36.6 | D7: 16 | E7: 31 | F7: 29.1 | G7: 25.5 | H7: 23.5 | I7: 22 | J7: 32 | K7: 29.7 | L7: 25.7 | M7: 24 | N7: 23 | O7: 31.5 | P7: 31 | Q7: 26.5 | R7: 24.5 | S7: 23
A8: 6 | B8: Y | C8: 35.4 | D8: 16 | E8: 30 | F8: 25.5 | G8: 23 | H8: 22.5 | I8: 21.5 | J8: 30.1 | K8: 26 | L8: 24.1 | M8: 23 | N8: 22 | O8: 30 | P8: 27 | Q8: 25 | R8: 23 | S8: 22
A9: 7 | B9: N | C9: 35.4 | D9: 16 | E9: 30.5 | F9: 26 | G9: 23.5 | H9: 22.7 | I9: 21 | J9: 30 | K9: 27 | L9: 24.5 | M9: 23.7 | N9: 21 | O9: 30.5 | P9: 28 | Q9: 25.5 | R9: 23 | S9: 21.5
A10: 8 | B10: N | C10: 36.7 | D10: 16 | E10: 30 | F10: 26 | G10: 24.3 | H10: 22.9 | I10: 21.5 | J10: 30.2 | K10: 26.5 | L10: 24.7 | M10: 23.5 | N10: 22 | O10: 30 | P10: 26.7 | Q10: 25.8 | R10: 25 | S10: 23
A11: 9 | B11: N | C11: 36.1 | D11: 16 | E11: 30 | F11: 26.7 | G11: 24.5 | H11: 23.8 | I11: 22.1 | J11: 30.5 | K11: 27 | L11: 26 | M11: 24 | N11: 23 | O11: 30.1 | P11: 28 | Q11: 26 | R11: 24 | S11: 24
A12: 10 | B12: Y | C12: 36.6 | D12: 16 | E12: 29.5 | F12: 26.05 | G12: 23.6 | H12: 22.5 | I12: 21.8 | J12: 30.2 | K12: 26.5 | L12: 24 | M12: 23 | N12: 22 | O12: 30.1 | P12: 27.5 | Q12: 25.8 | R12: 24.4 | S12: 23 | U12: =AVERAGEIF(B3:B15,"=Y",E3:E15) -> 29.78
A13: 11 | B13: N | C13: 36.6 | D13: 16 | E13: 30 | F13: 26.32 | G13: 23.9 | H13: 22.7 | I13: 21.9 | J13: 30.5 | K13: 26.58 | L13: 24.5 | M13: 23.3 | N13: 23 | O13: 29.1 | P13: 28.2 | Q13: 25.6 | R13: 24.6 | S13: 23.5 | U13: =AVERAGEIF(B4:B16,"=N",E4:E16) -> 30.185714
A14: 12 | B14: Y | C14: 36.4 | D14: 16 | E14: 28.9 | F14: 23.7 | G14: 23.9 | H14: 23 | I14: 22.2 | J14: 29 | K14: 26 | L14: 24 | M14: 23 | N14: 22.8 | O14: 29 | P14: 26 | Q14: 23.4 | R14: 21.9 | S14: 20.5
A15: 13 | B15: N | C15: 36.4 | D15: 16 | E15: 29.5 | F15: 24.5 | G15: 24.4 | H15: 23.5 | I15: 22.7 | J15: 30.5 | K15: 26.5 | L15: 25.4 | M15: 23.7 | N15: 23 | O15: 29.5 | P15: 26.5 | Q15: 25.5 | R15: 23.2 | S15: 20.5
A16: 14 | B16: Y | C16: 36.7 | D16: 18 | E16: 29.3 | F16: 25.8 | G16: 24.5 | H16: 23.4 | I16: 22.2 | J16: 30.5 | K16: 26 | L16: 25 | M16: 24 | N16: 22.6 | O16: 29.1 | P16: 27.5 | Q16: 25.8 | R16: 24 | S16: 22.2
A17: 15 | B17: N | C17: 36.7 | D17: 18 | E17: 30.2 | F17: 26.5 | G17: 24.8 | H17: 23.6 | I17: 22.8 | J17: 30.8 | K17: 26.2 | L17: 25.5 | M17: 24.3 | N17: 23 | O17: 29.3 | P17: 28.1 | Q17: 26.5 | R17: 25.2 | S17: 23.7
A18: 16 | B18: Y | C18: 35.2 | D18: 18 | E18: 31.2 | F18: 27.5 | G18: 26.2 | H18: 24 | I18: 20.6 | J18: 31 | K18: 28 | L18: 26.6 | M18: 24.2 | N18: 21 | O18: 30 | P18: 28.2 | Q18: 27 | R18: 24 | S18: 20.5
A19: 17 | B19: N | C19: 35.2 | D19: 18 | E19: 31.6 | F19: 28 | G19: 26.5 | H19: 24.5 | I19: 20.5 | J19: 31.2 | K19: 28.2 | L19: 26.8 | M19: 24.8 | N19: 21 | O19: 31.5 | P19: 28.5 | Q19: 28 | R19: 25 | S19: 20.8
A20: 18 | B20: Y | C20: 36.8 | D20: 18 | E20: 30.5 | F20: 26.7 | G20: 24 | H20: 21 | I20: 20.5 | J20: 31.4 | K20: 27 | L20: 24.2 | M20: 21.5 | N20: 20 | O20: 30.5 | P20: 27.8 | Q20: 24 | R20: 22 | S20: 21
A21: 19 | B21: N | C21: 36.8 | D21: 18 | E21: 30.8 | F21: 27.3 | G21: 24.5 | H21: 21.2 | I21: 21 | J21: 31.8 | K21: 28.1 | L21: 24.8 | M21: 21.5 | N21: 21.3 | O21: 30.5 | P21: 28.5 | Q21: 24.5 | R21: 22.5 | S21: 22
A22: 20 | B22: N | C22: 36.2 | D22: 18 | E22: 31.1 | F22: 27.5 | G22: 25.1 | H22: 24.2 | I22: 23.6 | J22: 31.5 | K22: 28.5 | L22: 25.8 | M22: 24.5 | N22: 24 | O22: 30 | P22: 28.5 | Q22: 26 | R22: 24.7 | S22: 23
A23: 21 | B23: N | C23: 36.6 | D23: 18 | E23: 29.9 | F23: 26.5 | G23: 24.5 | H23: 23.5 | I23: 22.4 | J23: 30.2 | K23: 27 | L23: 24.8 | M23: 24 | N23: 22 | O23: 30 | P23: 27.4 | Q23: 25 | R23: 24.3 | S23: 22
A24: 22 | B24: Y | C24: 36.8 | D24: 18 | E24: 29.8 | F24: 25.3 | G24: 24.4 | H24: 23.8 | I24: 23 | J24: 30.8 | K24: 26.3 | L24: 25.1 | M24: 24.5 | N24: 23.8 | O24: 29.2 | P24: 25.5 | Q24: 26.6 | R24: 23.3 | S24: 21.5
A25: 23 | B25: N | C25: 36.8 | D25: 18 | E25: 30.7 | F25: 25.4 | G25: 24.9 | H25: 23.8 | I25: 23.2 | J25: 31.7 | K25: 27 | L25: 25.9 | M25: 24.4 | N25: 24 | O25: 29.3 | P25: 25.5 | Q25: 26.5 | R25: 22 | S25: 23.3
... A70: 68 | B70: N | C70: 36.6 | D70: 25 | E70: 32.8 | F70: 30.1 | G70: 28.5 | H70: 28.4 | I70: 27.7 | J70: 33.2 | K70: 30.6 | L70: 29.3 | M70: 28.7 | N70: 28.8 | O70: 28.9 | P70: 29.1 | Q70: 26.6 | R70: 24.2 | S70: 24.6

Sheet MLX_P
D1: PIMORONI CAMERA (MLX_P)
A2: =Raw_Data!B2 -> glasses | B2: BODY TEMP | C2: AB TEMP | D2: =Raw_Data!E2 -> 1M | E2: =Raw_Data!F2 -> 2M | F2: =Raw_Data!G2 -> 3M | G2: =Raw_Data!H2 -> 4M | H2: =Raw_Data!I2 -> 5M
A3: =Raw_Data!B3 -> N | B3: =Raw_Data!C3 -> 36.8 | C3: 16 | D3: =Raw_Data!E3 -> 30.3 | E3: =Raw_Data!F3 -> 25.5 | F3: =Raw_Data!G3 -> 23 | G3: =Raw_Data!H3 -> 22.06 | H3: =Raw_Data!I3 -> 21.5
A4: =Raw_Data!B4 -> Y | B4: =Raw_Data!C4 -> 36.8 | C4: 16 | D4: =Raw_Data!E4 -> 30 | E4: =Raw_Data!F4 -> 29.5 | F4: =Raw_Data!G4 -> 26 | G4: =Raw_Data!H4 -> 24.5 | H4: =Raw_Data!I4 -> 22.5
A5: =Raw_Data!B5 -> N | B5: =Raw_Data!C5 -> 36.8 | C5: 16 | D5: =Raw_Data!E5 -> 30.3 | E5: =Raw_Data!F5 -> 30 | F5: =Raw_Data!G5 -> 25.5 | G5: =Raw_Data!H5 -> 23.5 | H5: =Raw_Data!I5 -> 22
A6: =Raw_Data!B6 -> Y | B6: =Raw_Data!C6 -> 36.6 | C6: 16 | D6: =Raw_Data!E6 -> 30.5 | E6: =Raw_Data!F6 -> 27.9 | F6: =Raw_Data!G6 -> 25.2 | G6: =Raw_Data!H6 -> 23 | H6: =Raw_Data!I6 -> 21.7
A7: =Raw_Data!B7 -> N | B7: =Raw_Data!C7 -> 36.6 | C7: 16 | D7: =Raw_Data!E7 -> 31 | E7: =Raw_Data!F7 -> 29.1 | F7: =Raw_Data!G7 -> 25.5 | G7: =Raw_Data!H7 -> 23.5 | H7: =Raw_Data!I7 -> 22
A8: =Raw_Data!B8 -> Y | B8: =Raw_Data!C8 -> 35.4 | C8: 16 | D8: =Raw_Data!E8 -> 30 | E8: =Raw_Data!F8 -> 25.5 | F8: =Raw_Data!G8 -> 23 | G8: =Raw_Data!H8 -> 22.5 | H8: =Raw_Data!I8 -> 21.5
A9: =Raw_Data!B9 -> N | B9: =Raw_Data!C9 -> 35.4 | C9: 16 | D9: =Raw_Data!E9 -> 30.5 | E9: =Raw_Data!F9 -> 26 | F9: =Raw_Data!G9 -> 23.5 | G9: =Raw_Data!H9 -> 22.7 | H9: =Raw_Data!I9 -> 21
A10: =Raw_Data!B10 -> N | B10: =Raw_Data!C10 -> 36.7 | C10: 16 | D10: =Raw_Data!E10 -> 30 | E10: =Raw_Data!F10 -> 26 | F10: =Raw_Data!G10 -> 24.3 | G10: =Raw_Data!H10 -> 22.9 | H10: =Raw_Data!I10 -> 21.5
A11: =Raw_Data!B11 -> N | B11: =Raw_Data!C11 -> 36.1 | C11: 16 | D11: =Raw_Data!E11 -> 30 | E11: =Raw_Data!F11 -> 26.7 | F11: =Raw_Data!G11 -> 24.5 | G11: =Raw_Data!H11 -> 23.8 | H11: =Raw_Data!I11 -> 22.1
A12: =Raw_Data!B12 -> Y | B12: =Raw_Data!C12 -> 36.6 | C12: 16 | D12: =Raw_Data!E12 -> 29.5 | E12: =Raw_Data!F12 -> 26.05 | F12: =Raw_Data!G12 -> 23.6 | G12: =Raw_Data!H12 -> 22.5 | H12: =Raw_Data!I12 -> 21.8
A13: =Raw_Data!B13 -> N | B13: =Raw_Data!C13 -> 36.6 | C13: 16 | D13: =Raw_Data!E13 -> 30 | E13: =Raw_Data!F13 -> 26.32 | F13: =Raw_Data!G13 -> 23.9 | G13: =Raw_Data!H13 -> 22.7 | H13: =Raw_Data!I13 -> 21.9
A14: =Raw_Data!B14 -> Y | B14: =Raw_Data!C14 -> 36.4 | C14: 16 | D14: =Raw_Data!E14 -> 28.9 | E14: =Raw_Data!F14 -> 23.7 | F14: =Raw_Data!G14 -> 23.9 | G14: =Raw_Data!H14 -> 23 | H14: =Raw_Data!I14 -> 22.2
A15: =Raw_Data!B15 -> N | B15: =Raw_Data!C15 -> 36.4 | C15: 16 | D15: =Raw_Data!E15 -> 29.5 | E15: =Raw_Data!F15 -> 24.5 | F15: =Raw_Data!G15 -> 24.4 | G15: =Raw_Data!H15 -> 23.5 | H15: =Raw_Data!I15 -> 22.7
C16: AVERAGE_IF_EYEGLASSES_Y | D16: =AVERAGEIF(A3:A15,"=Y",D3:D15) -> 29.78 | E16: =AVERAGEIF(A3:A15,"=Y",E3:E15) -> 26.53 | F16: =AVERAGEIF(A3:A15,"=Y",F3:F15) -> 24.34 | G16: =AVERAGEIF(A3:A15,"=Y",G3:G15) -> 23.1 | H16: =AVERAGEIF(A3:A15,"=Y",H3:H15) -> 21.94
C17: SD | D17: =_xlfn.STDEV.S(D4,D6,D8,D12,D14) -> 0.60580525 | E17: =_xlfn.STDEV.S(E4,E6,E8,E12,E14) -> 2.2359562 | F17: =_xlfn.STDEV.S(F4,F6,F8,F12,F14) -> 1.2280065 | G17: =_xlfn.STDEV.S(G4,G6,G8,G12,G14) -> 0.82158384 | H17: =_xlfn.STDEV.S(H4,H6,H8,H12,H14) -> 0.40373258
C18: AVERAGE_IF_EYEGLASSES_N | D18: =AVERAGEIF(A3:A15,"=N",D3:D15) -> 30.2 | E18: =AVERAGEIF(A3:A15,"=N",E3:E15) -> 26.765 | F18: =AVERAGEIF(A3:A15,"=N",F3:F15) -> 24.325 | G18: =AVERAGEIF(A3:A15,"=N",G3:G15) -> 23.0825 | H18: =AVERAGEIF(A3:A15,"=N",H3:H15) -> 21.8375
C19: SD | D19: =_xlfn.STDEV.S(D3,D5,D7,D9,D10,D11,D13,D15) -> 0.44077853 | E19: =_xlfn.STDEV.S(E3,E5,E7,E9,E10,E11,E13,E15) -> 1.8524347 | F19: =_xlfn.STDEV.S(F3,F5,F7,F9,F10,F11,F13,F15) -> 0.87952909 | G19: =_xlfn.STDEV.S(G3,G5,G7,G9,G10,G11,G13,G15) -> 0.58665517 | H19: =_xlfn.STDEV.S(H3,H5,H7,H9,H10,H11,H13,H15) -> 0.50691645
A21: =$A$2 -> glasses | B21: =B2 -> BODY TEMP | C21: =C2 -> AB TEMP | D21: =D2 -> 1M | E21: =E2 -> 2M | F21: =F2 -> 3M | G21: =G2 -> 4M | H21: =H2 -> 5M
A22: =Raw_Data!B16 -> Y | B22: =Raw_Data!C16 -> 36.7 | C22: =Raw_Data!D16 -> 18 | D22: =Raw_Data!E16 -> 29.3 | E22: =Raw_Data!F16 -> 25.8 | F22: =Raw_Data!G16 -> 24.5 | G22: =Raw_Data!H16 -> 23.4 | H22: =Raw_Data!I16 -> 22.2
A23: =Raw_Data!B17 -> N | B23: =Raw_Data!C17 -> 36.7 | C23: =Raw_Data!D17 -> 18 | D23: =Raw_Data!E17 -> 30.2 | E23: =Raw_Data!F17 -> 26.5 | F23: =Raw_Data!G17 -> 24.8 | G23: =Raw_Data!H17 -> 23.6 | H23: =Raw_Data!I17 -> 22.8
A24: =Raw_Data!B18 -> Y | B24: =Raw_Data!C18 -> 35.2 | C24: =Raw_Data!D18 -> 18 | D24: =Raw_Data!E18 -> 31.2 | E24: =Raw_Data!F18 -> 27.5 | F24: =Raw_Data!G18 -> 26.2 | G24: =Raw_Data!H18 -> 24 | H24: =Raw_Data!I18 -> 20.6
A25: =Raw_Data!B19 -> N | B25: =Raw_Data!C19 -> 35.2 | C25: =Raw_Data!D19 -> 18 | D25: =Raw_Data!E19 -> 31.6 | E25: =Raw_Data!F19 -> 28 | F25: =Raw_Data!G19 -> 26.5 | G25: =Raw_Data!H19 -> 24.5 | H25: =Raw_Data!I19 -> 20.5
A26: =Raw_Data!B20 -> Y | B26: =Raw_Data!C20 -> 36.8 | C26: =Raw_Data!D20 -> 18 | D26: =Raw_Data!E20 -> 30.5 | E26: =Raw_Data!F20 -> 26.7 | F26: =Raw_Data!G20 -> 24 | G26: =Raw_Data!H20 -> 21 | H26: =Raw_Data!I20 -> 20.5
A27: =Raw_Data!B21 -> N | B27: =Raw_Data!C21 -> 36.8 | C27: =Raw_Data!D21 -> 18 | D27: =Raw_Data!E21 -> 30.8 | E27: =Raw_Data!F21 -> 27.3 | F27: =Raw_Data!G21 -> 24.5 | G27: =Raw_Data!H21 -> 21.2 | H27: =Raw_Data!I21 -> 21
A28: =Raw_Data!B22 -> N | B28: =Raw_Data!C22 -> 36.2 | C28: =Raw_Data!D22 -> 18 | D28: =Raw_Data!E22 -> 31.1 | E28: =Raw_Data!F22 -> 27.5 | F28: =Raw_Data!G22 -> 25.1 | G28: =Raw_Data!H22 -> 24.2 | H28: =Raw_Data!I22 -> 23.6
A29: =Raw_Data!B23 -> N | B29: =Raw_Data!C23 -> 36.6 | C29: =Raw_Data!D23 -> 18 | D29: =Raw_Data!E23 -> 29.9 | E29: =Raw_Data!F23 -> 26.5 | F29: =Raw_Data!G23 -> 24.5 | G29: =Raw_Data!H23 -> 23.5 | H29: =Raw_Data!I23 -> 22.4
A30: =Raw_Data!B24 -> Y | B30: =Raw_Data!C24 -> 36.8 | C30: =Raw_Data!D24 -> 18 | D30: =Raw_Data!E24 -> 29.8 | E30: =Raw_Data!F24 -> 25.3 | F30: =Raw_Data!G24 -> 24.4 | G30: =Raw_Data!H24 -> 23.8 | H30: =Raw_Data!I24 -> 23
A31: =Raw_Data!B25 -> N | B31: =Raw_Data!C25 -> 36.8 | C31: =Raw_Data!D25 -> 18 | D31: =Raw_Data!E25 -> 30.7 | E31: =Raw_Data!F25 -> 25.4 | F31: =Raw_Data!G25 -> 24.9 | G31: =Raw_Data!H25 -> 23.8 | H31: =Raw_Data!I25 -> 23.2
A32: =Raw_Data!B26 -> N | B32: =Raw_Data!C26 -> 36.8 | C32: =Raw_Data!D26 -> 18 | D32: =Raw_Data!E26 -> 29.9 | E32: =Raw_Data!F26 -> 26.3 | F32: =Raw_Data!G26 -> 24.2 | G32: =Raw_Data!H26 -> 23.1 | H32: =Raw_Data!I26 -> 22.4
C33: AVERAGE_IF_EYEGLASSES_Y | D33: =AVERAGEIF(A22:A32,"=Y",D22:D32) -> 30.2 | E33: =AVERAGEIF(A22:A32,"=Y",E22:E32) -> 26.325 | F33: =AVERAGEIF(A22:A32,"=Y",F22:F32) -> 24.775 | G33: =AVERAGEIF(A22:A32,"=Y",G22:G32) -> 23.05 | H33: =AVERAGEIF(A22:A32,"=Y",H22:H32) -> 21.575
C34: SD | D34: =_xlfn.STDEV.S(D22,D24,D26,D30) -> 0.82865353 | E34: =_xlfn.STDEV.S(E22,E24,E26,E30) -> 0.97425185 | F34: =_xlfn.STDEV.S(F22,F24,F26,F30) -> 0.97425185 | G34: =_xlfn.STDEV.S(G22,G24,G26,G30) -> 1.3892444 | H34: =_xlfn.STDEV.S(H22,H24,H26,H30) -> 1.2284814
C35: AVERAGE_IF_EYEGLASSES_N | D35: =AVERAGEIF(A22:A32,"=N",D22:D32) -> 30.6 | E35: =AVERAGEIF(A22:A32,"=N",E22:E32) -> 26.785714 | F35: =AVERAGEIF(A22:A32,"=N",F22:F32) -> 24.928571 | G35: =AVERAGEIF(A22:A32,"=N",G22:G32) -> 23.414286 | H35: =AVERAGEIF(A22:A32,"=N",H22:H32) -> 22.271429
C36: SD | D36: =_xlfn.STDEV.S(D23,D25,D27,D28,D29,D31,D32) -> 0.63770422 | E36: =_xlfn.STDEV.S(E23,E25,E27,E28,E29,E31,E32) -> 0.87259875 | F36: =_xlfn.STDEV.S(F23,F25,F27,F28,F29,F31,F32) -> 0.75435245 | G36: =_xlfn.STDEV.S(G23,G25,G27,G28,G29,G31,G32) -> 1.0792414 | H36: =_xlfn.STDEV.S(H23,H25,H27,H28,H29,H31,H32) -> 1.1324226
B38: =B21 -> BODY TEMP | C38: =C21 -> AB TEMP | D38: =D21 -> 1M | E38: =E21 -> 2M | F38: =F21 -> 3M | G38: =G21 -> 4M | H38: =H21 -> 5M
A39: =Raw_Data!B27 -> N | B39: =Raw_Data!C27 -> 36.6 | C39: =Raw_Data!D27 -> 20 | D39: =Raw_Data!E27 -> 30.5 | E39: =Raw_Data!F27 -> 27.6 | F39: =Raw_Data!G27 -> 25.8 | G39: =Raw_Data!H27 -> 24.5 | H39: =Raw_Data!I27 -> 23.5
A40: =Raw_Data!B28 -> N | B40: =Raw_Data!C28 -> 36.4 | C40: =Raw_Data!D28 -> 20 | D40: =Raw_Data!E28 -> 30.6 | E40: =Raw_Data!F28 -> 26.4 | F40: =Raw_Data!G28 -> 25.5 | G40: =Raw_Data!H28 -> 24.6 | H40: =Raw_Data!I28 -> 23
A41: =Raw_Data!B29 -> Y | B41: =Raw_Data!C29 -> 36.9 | C41: =Raw_Data!D29 -> 20 | D41: =Raw_Data!E29 -> 30.2 | E41: =Raw_Data!F29 -> 28 | F41: =Raw_Data!G29 -> 25.8 | G41: =Raw_Data!H29 -> 24.5 | H41: =Raw_Data!I29 -> 22.5
A42: =Raw_Data!B30 -> N | B42: =Raw_Data!C30 -> 36.9 | C42: =Raw_Data!D30 -> 20 | D42: =Raw_Data!E30 -> 30.8 | E42: =Raw_Data!F30 -> 28.5 | F42: =Raw_Data!G30 -> 26 | G42: =Raw_Data!H30 -> 25 | H42: =Raw_Data!I30 -> 22.8
...

Sheet MLX_P_AVG&SD
A1: Average Values for MLX-P at different ambient temp where eye-glasses is Y | I1: S.D Values for MLX-P at different ambient temp where eye-glasses is Y
A2: =[1]Avarageateachdistance!A1 -> Distance | B2: MLX-P at 16 Degrees Y | C2: MLX-P at 18 Degrees Y | D2: MLX-P at 20 degrees Y | E2: MLX-P at 22 degrees Y | F2: MLX-P at 24 degrees Y | G2: MLX-P at 25 degrees Y | I2: Distance | J2: MLX-P at 16 degrees | K2: MLX-P at 18 Degrees | L2: MLX-P at 20 degrees | M2: MLX-P at 22 degrees | N2: MLX-P at 24 degrees | O2: MLX-P at 25 degrees
A3: 1 | B3: =MLX_P!D16 -> 29.78 | C3: =MLX_P!D33 -> 30.2 | D3: =MLX_P!D47 -> 30.733333 | E3: =MLX_P!D63 -> 30.46 | F3: =MLX_P!D82 -> 32.1 | G3: =MLX_P!D101 -> 31.775 | I3: 1 | J3: =MLX_P!D17 -> 0.60580525 | K3: =MLX_P!D34 -> 0.82865353 | L3: =MLX_P!D48 -> 0.68068593 | M3: =MLX_P!D64 -> 0.64093681 | N3: =MLX_P!D83 -> 0.56124861 | O3: =MLX_P!D102 -> 0.25
A4: 2 | B4: =MLX_P!E16 -> 26.53 | C4: =MLX_P!E33 -> 26.325 | D4: =MLX_P!E47 -> 28.333333 | E4: =MLX_P!E63 -> 28.233333 | F4: =MLX_P!E82 -> 30.82 | G4: =MLX_P!E101 -> 29.9 | I4: 2 | J4: =MLX_P!E17 -> 2.2359562 | K4: =MLX_P!E34 -> 0.97425185 | L4: =MLX_P!E48 -> 0.57735027 | M4: =MLX_P!E64 -> 1.123981 | N4: =MLX_P!E83 -> 0.77910205 | O4: =MLX_P!E102 -> 0.49665548
A5: 3 | B5: =MLX_P!F16 -> 24.34 | C5: =MLX_P!F33 -> 24.775 | D5: =MLX_P!F47 -> 26.5 | E5: =MLX_P!F63 -> 27.366667 | F5: =MLX_P!F82 -> 28.96 | G5: =MLX_P!F101 -> 29.1 | I5: 3 | J5: =MLX_P!F17 -> 1.2280065 | K5: =MLX_P!F34 -> 0.97425185 | L5: =MLX_P!F48 -> 0.7 | M5: =MLX_P!F64 -> 1.0598742 | N5: =MLX_P!F83 -> 1.0261579 | O5: =MLX_P!F102 -> 0.84852814
A6: 4 | B6: =MLX_P!G16 -> 23.1 | C6: =MLX_P!G33 -> 23.05 | D6: =MLX_P!G47 -> 25.033333 | E6: =MLX_P!G63 -> 26.3 | F6: =MLX_P!G82 -> 27.64 | G6: =MLX_P!G101 -> 28.325 | I6: 4 | J6: =MLX_P!G17 -> 0.82158384 | K6: =MLX_P!G34 -> 1.3892444 | L6: =MLX_P!G48 -> 0.68068593 | M6: =MLX_P!G64 -> 1.0816654 | N6: =MLX_P!G83 -> 0.86486993 | O6: =MLX_P!G102 -> 0.60759087
A7: 5 | B7: =MLX_P!H16 -> 21.94 | C7: =MLX_P!H33 -> 21.575 | D7: =MLX_P!H47 -> 22.5 | E7: =MLX_P!H63 -> 24.433333 | F7: =MLX_P!H82 -> 26.66 | G7: =MLX_P!H101 -> 27.65 | I7: 5 | J7: =MLX_P!H17 -> 0.40373258 | K7: =MLX_P!H34 -> 1.2284814 | L7: =MLX_P!H48 -> 0.5 | M7: =MLX_P!H64 -> 1.0692677 | N7: =MLX_P!H83 -> 0.91268834 | O7: =MLX_P!H102 -> 0.5
A11: Average Values for MLX-P at different ambient temp where eye-glasses is N | I11: S.D Values for MLX-P at different ambient temp where eye-glasses is N
A12: Distance | B12: MLX-P at 16 Degrees N | C12: MLX-P at 18 Degrees N | D12: MLX-P at 20 degrees N | E12: MLX-P at 22 degrees N | F12: MLX-P at 24 degrees N | G12: MLX-P at 25 degrees N | I12: Distance | J12: MLX-P at 16 degrees | K12: MLX-P at 18 Degrees | L12: MLX-P at 20 degrees | M12: MLX-P at 22 degrees | N12: MLX-P at 24 degrees | O12: MLX-P at 25 degrees
A13: 1 | B13: =MLX_P!D18 -> 30.2 | C13: =MLX_P!D35 -> 30.6 | D13: =MLX_P!D49 -> 30.92 | E13: =MLX_P!D65 -> 31.098571 | F13: =MLX_P!D84 -> 32.75 | G13: =MLX_P!D103 -> 32.4 | I13: 1 | J13: =MLX_P!D19 -> 0.44077853 | K13: =MLX_P!D36 -> 0.63770422 | L13: =MLX_P!D50 -> 0.47644517 | M13: =MLX_P!D66 -> 0.44588863 | N13: =MLX_P!D85 -> 0.72899148 | O13: =MLX_P!D104 -> 0.3082207
A14: 2 | B14: =MLX_P!E18 -> 26.765 | C14: =MLX_P!E35 -> 26.785714 | D14: =MLX_P!E49 -> 28.02 | E14: =MLX_P!E65 -> 28.185714 | F14: =MLX_P!E84 -> 31.075 | G14: =MLX_P!E103 -> 30.566667 | I14: 2 | J14: =MLX_P!E19 -> 1.8524347 | K14: =MLX_P!E36 -> 0.87259875 | L14: =MLX_P!E50 -> 1.068644 | M14: =MLX_P!E66 -> 0.87958323 | N14: =MLX_P!E85 -> 0.74976187 | O14: =MLX_P!E104 -> 0.50249378
A15: 3 | B15: =MLX_P!F18 -> 24.325 | C15: =MLX_P!F35 -> 24.928571 | D15: =MLX_P!F49 -> 26.32 | E15: =MLX_P!F65 -> 27 | F15: =MLX_P!F84 -> 29.2125 | G15: =MLX_P!F103 -> 29.455556 | I15: 3 | J15: =MLX_P!F19 -> 0.87952909 | K15: =MLX_P!F36 -> 0.75435245 | L15: =MLX_P!F50 -> 0.81670068 | M15: =MLX_P!F66 -> 0.48166378 | N15: =MLX_P!F85 -> 0.93874917 | O15: =MLX_P!F104 -> 0.75018516
A16: 4 | B16: =MLX_P!G18 -> 23.0825 | C16: =MLX_P!G35 -> 23.414286 | D16: =MLX_P!G49 -> 25.02 | E16: =MLX_P!G65 -> 26.157143 | F16: =MLX_P!G84 -> 27.7875 | G16: =MLX_P!G103 -> 28.611111 | I16: 4 | J16: =MLX_P!G19 -> 0.58665517 | K16: =MLX_P!G36 -> 1.0792414 | L16: =MLX_P!G50 -> 0.59329588 | M16: =MLX_P!G66 -> 0.51251016 | N16: =MLX_P!G85 -> 0.68959098 | O16: =MLX_P!G104 -> 0.61734197
A17: 5 | B17: =MLX_P!H18 -> 21.8375 | C17: =MLX_P!H35 -> 22.271429 | D17: =MLX_P!H49 -> 23.02 | E17: =MLX_P!H65 -> 24.271429 | F17: =MLX_P!H84 -> 26.9375 | G17: =MLX_P!H103 -> 27.6 | I17: 5 | J17: =MLX_P!H19 -> 0.50691645 | K17: =MLX_P!H36 -> 1.1324226 | L17: =MLX_P!H50 -> 0.39623226 | M17: =MLX_P!H66 -> 0.41190614 | N17: =MLX_P!H85 -> 0.63005102 | O17: =MLX_P!H104 -> 0.71937473

Sheet MLX_R
C1: ROBOT SHOP CAMERA (MLX_R)
A2: =Raw_Data!B2 -> glasses | B2: =Raw_Data!C2 -> body temp | C2: =Raw_Data!D2 -> ambient temp | D2: =Raw_Data!E2 -> 1M | E2: =Raw_Data!F2 -> 2M | F2: =Raw_Data!G2 -> 3M | G2: =Raw_Data!H2 -> 4M | H2: =Raw_Data!I2 -> 5M
A3: =Raw_Data!B3 -> N | B3: =Raw_Data!C3 -> 36.8 | C3: =Raw_Data!D3 -> 16 | D3: =Raw_Data!J3 -> 30.5 | E3: =Raw_Data!K3 -> 26 | F3: =Raw_Data!L3 -> 23.5 | G3: =Raw_Data!M3 -> 22.5 | H3: =Raw_Data!N3 -> 21
A4: =Raw_Data!B4 -> Y | B4: =Raw_Data!C4 -> 36.8 | C4: =Raw_Data!D4 -> 16 | D4: =Raw_Data!J4 -> 30.5 | E4: =Raw_Data!K4 -> 28.5 | F4: =Raw_Data!L4 -> 25.5 | G4: =Raw_Data!M4 -> 22.5 | H4: =Raw_Data!N4 -> 23
A5: =Raw_Data!B5 -> N | B5: =Raw_Data!C5 -> 36.8 | C5: =Raw_Data!D5 -> 16 | D5: =Raw_Data!J5 -> 30.8 | E5: =Raw_Data!K5 -> 29 | F5: =Raw_Data!L5 -> 25.3 | G5: =Raw_Data!M5 -> 23 | H5: =Raw_Data!N5 -> 23
A6: =Raw_Data!B6 -> Y | B6: =Raw_Data!C6 -> 36.6 | C6: =Raw_Data!D6 -> 16 | D6: =Raw_Data!J6 -> 31.2 | E6: =Raw_Data!K6 -> 28.5 | F6: =Raw_Data!L6 -> 25.4 | G6: =Raw_Data!M6 -> 24 | H6: =Raw_Data!N6 -> 22
A7: =Raw_Data!B7 -> N | B7: =Raw_Data!C7 -> 36.6 | C7: =Raw_Data!D7 -> 16 | D7: =Raw_Data!J7 -> 32 | E7: =Raw_Data!K7 -> 29.7 | F7: =Raw_Data!L7 -> 25.7 | G7: =Raw_Data!M7 -> 24 | H7: =Raw_Data!N7 -> 23
A8: =Raw_Data!B8 -> Y | B8: =Raw_Data!C8 -> 35.4 | C8: =Raw_Data!D8 -> 16 | D8: =Raw_Data!J8 -> 30.1 | E8: =Raw_Data!K8 -> 26 | F8: =Raw_Data!L8 -> 24.1 | G8: =Raw_Data!M8 -> 23 | H8: =Raw_Data!N8 -> 22
A9: =Raw_Data!B9 -> N | B9: =Raw_Data!C9 -> 35.4 | C9: =Raw_Data!D9 -> 16 | D9: =Raw_Data!J9 -> 30 | E9: =Raw_Data!K9 -> 27 | F9: =Raw_Data!L9 -> 24.5 | G9: =Raw_Data!M9 -> 23.7 | H9: =Raw_Data!N9 -> 21
A10: =Raw_Data!B10 -> N | B10: =Raw_Data!C10 -> 36.7 | C10: =Raw_Data!D10 -> 16 | D10: =Raw_Data!J10 -> 30.2 | E10: =Raw_Data!K10 -> 26.5 | F10: =Raw_Data!L10 -> 24.7 | G10: =Raw_Data!M10 -> 23.5 | H10: =Raw_Data!N10 -> 22
A11: =Raw_Data!B11 -> N | B11: =Raw_Data!C11 -> 36.1 | C11: =Raw_Data!D11 -> 16 | D11: =Raw_Data!J11 -> 30.5 | E11: =Raw_Data!K11 -> 27 | F11: =Raw_Data!L11 -> 26 | G11: =Raw_Data!M11 -> 24 | H11: =Raw_Data!N11 -> 23
A12: =Raw_Data!B12 -> Y | B12: =Raw_Data!C12 -> 36.6 | C12: =Raw_Data!D12 -> 16 | D12: =Raw_Data!J12 -> 30.2 | E12: =Raw_Data!K12 -> 26.5 | F12: =Raw_Data!L12 -> 24 | G12: =Raw_Data!M12 -> 23 | H12: =Raw_Data!N12 -> 22
A13: =Raw_Data!B13 -> N | B13: =Raw_Data!C13 -> 36.6 | C13: =Raw_Data!D13 -> 16 | D13: =Raw_Data!J13 -> 30.5 | E13: =Raw_Data!K13 -> 26.58 | F13: =Raw_Data!L13 -> 24.5 | G13: =Raw_Data!M13 -> 23.3 | H13: =Raw_Data!N13 -> 23
A14: =Raw_Data!B14 -> Y | B14: =Raw_Data!C14 -> 36.4 | C14: =Raw_Data!D14 -> 16 | D14: =Raw_Data!J14 -> 29 | E14: =Raw_Data!K14 -> 26 | F14: =Raw_Data!L14 -> 24 | G14: =Raw_Data!M14 -> 23 | H14: =Raw_Data!N14 -> 22.8
A15: =Raw_Data!B15 -> N | B15: =Raw_Data!C15 -> 36.4 | C15: =Raw_Data!D15 -> 16 | D15: =Raw_Data!J15 -> 30.5 | E15: =Raw_Data!K15 -> 26.5 | F15: =Raw_Data!L15 -> 25.4 | G15: =Raw_Data!M15 -> 23.7 | H15: =Raw_Data!N15 -> 23
C16: AVERAGE_IF_EYEGLASSES_Y | D16: =AVERAGEIF(A3:A15,"=Y",D3:D15) -> 30.2 | E16: =AVERAGEIF(A3:A15,"=Y",E3:E15) -> 27.1 | F16: =AVERAGEIF(A3:A15,"=Y",F3:F15) -> 24.6 | G16: =AVERAGEIF(A3:A15,"=Y",G3:G15) -> 23.1 | H16: =AVERAGEIF(A3:A15,"=Y",H3:H15) -> 22.36
C17: SD | D17: =_xlfn.STDEV.S(D4,D6,D8,D12,D14) -> 0.79686887 | E17: =_xlfn.STDEV.S(E4,E6,E8,E12,E14) -> 1.2942179 | F17: =_xlfn.STDEV.S(F4,F6,F8,F12,F14) -> 0.77781746 | G17: =_xlfn.STDEV.S(G4,G6,G8,G12,G14) -> 0.54772256 | H17: =_xlfn.STDEV.S(H4,H6,H8,H12,H14) -> 0.49799598
C18: AVERAGE_IF_EYEGLASSES_N | D18: =AVERAGEIF(A3:A15,"=N",D3:D15) -> 30.625 | E18: =AVERAGEIF(A3:A15,"=N",E3:E15) -> 27.285 | F18: =AVERAGEIF(A3:A15,"=N",F3:F15) -> 24.95 | G18: =AVERAGEIF(A3:A15,"=N",G3:G15) -> 23.4625 | H18: =AVERAGEIF(A3:A15,"=N",H3:H15) -> 22.375
C19: SD | D19: =_xlfn.STDEV.S(D3,D5,D7,D9,D10,D11,D13,D15) -> 0.6041523 | E19: =_xlfn.STDEV.S(E3,E5,E7,E9,E10,E11,E13,E15) -> 1.3264668 | F19: =_xlfn.STDEV.S(F3,F5,F7,F9,F10,F11,F13,F15) -> 0.80711125 | G19: =_xlfn.STDEV.S(G3,G5,G7,G9,G10,G11,G13,G15) -> 0.51530158 | H19: =_xlfn.STDEV.S(H3,H5,H7,H9,H10,H11,H13,H15) -> 0.91612538
A21: =$A$2 -> glasses | B21: =B2 -> body temp | C21: =C2 -> ambient temp | D21: =D2 -> 1M | E21: =E2 -> 2M | F21: =F2 -> 3M | G21: =G2 -> 4M | H21: =H2 -> 5M
A22: =Raw_Data!B16 -> Y | B22: =Raw_Data!C16 -> 36.7 | C22: =Raw_Data!D16 -> 18 | D22: =Raw_Data!J16 -> 30.5 | E22: =Raw_Data!K16 -> 26 | F22: =Raw_Data!L16 -> 25 | G22: =Raw_Data!M16 -> 24 | H22: =Raw_Data!N16 -> 22.6
A23: =Raw_Data!B17 -> N | B23: =Raw_Data!C17 -> 36.7 | C23: =Raw_Data!D17 -> 18 | D23: =Raw_Data!J17 -> 30.8 | E23: =Raw_Data!K17 -> 26.2 | F23: =Raw_Data!L17 -> 25.5 | G23: =Raw_Data!M17 -> 24.3 | H23: =Raw_Data!N17 -> 23
A24: =Raw_Data!B18 -> Y | B24: =Raw_Data!C18 -> 35.2 | C24: =Raw_Data!D18 -> 18 | D24: =Raw_Data!J18 -> 31 | E24: =Raw_Data!K18 -> 28 | F24: =Raw_Data!L18 -> 26.6 | G24: =Raw_Data!M18 -> 24.2 | H24: =Raw_Data!N18 -> 21
A25: =Raw_Data!B19 -> N | B25: =Raw_Data!C19 -> 35.2 | C25: =Raw_Data!D19 -> 18 | D25: =Raw_Data!J19 -> 31.2 | E25: =Raw_Data!K19 -> 28.2 | F25: =Raw_Data!L19 -> 26.8 | G25: =Raw_Data!M19 -> 24.8 | H25: =Raw_Data!N19 -> 21
A26: =Raw_Data!B20 -> Y | B26: =Raw_Data!C20 -> 36.8 | C26: =Raw_Data!D20 -> 18 | D26: =Raw_Data!J20 -> 31.4 | E26: =Raw_Data!K20 -> 27 | F26: =Raw_Data!L20 -> 24.2 | G26: =Raw_Data!M20 -> 21.5 | H26: =Raw_Data!N20 -> 20
A27: =Raw_Data!B21 -> N | B27: =Raw_Data!C21 -> 36.8 | C27: =Raw_Data!D21 -> 18 | D27: =Raw_Data!J21 -> 31.8 | E27: =Raw_Data!K21 -> 28.1 | F27: =Raw_Data!L21 -> 24.8 | G27: =Raw_Data!M21 -> 21.5 | H27: =Raw_Data!N21 -> 21.3
A28: =Raw_Data!B22 -> N | B28: =Raw_Data!C22 -> 36.2 | C28: =Raw_Data!D22 -> 18 | D28: =Raw_Data!J22 -> 31.5 | E28: =Raw_Data!K22 -> 28.5 | F28: =Raw_Data!L22 -> 25.8 | G28: =Raw_Data!M22 -> 24.5 | H28: =Raw_Data!N22 -> 24
A29: =Raw_Data!B23 -> N | B29: =Raw_Data!C23 -> 36.6 | C29: =Raw_Data!D23 -> 18 | D29: =Raw_Data!J23 -> 30.2 | E29: =Raw_Data!K23 -> 27 | F29: =Raw_Data!L23 -> 24.8 | G29: =Raw_Data!M23 -> 24 | H29: =Raw_Data!N23 -> 22
A30: =Raw_Data!B24 -> Y | B30: =Raw_Data!C24 -> 36.8 | C30: =Raw_Data!D24 -> 18 | D30: =Raw_Data!J24 -> 30.8 | E30: =Raw_Data!K24 -> 26.3 | F30: =Raw_Data!L24 -> 25.1 | G30: =Raw_Data!M24 -> 24.5 | H30: =Raw_Data!N24 -> 23.8
A31: =Raw_Data!B25 -> N | B31: =Raw_Data!C25 -> 36.8 | C31: =Raw_Data!D25 -> 18 | D31: =Raw_Data!J25 -> 31.7 | E31: =Raw_Data!K25 -> 27 | F31: =Raw_Data!L25 -> 25.9 | G31: =Raw_Data!M25 -> 24.4 | H31: =Raw_Data!N25 -> 24
A32: =Raw_Data!B26 -> N | B32: =Raw_Data!C26 -> 36.8 | C32: =Raw_Data!D26 -> 18 | D32: =Raw_Data!J26 -> 30.2 | E32: =Raw_Data!K26 -> 27 | F32: =Raw_Data!L26 -> 24.8 | G32: =Raw_Data!M26 -> 24.2 | H32: =Raw_Data!N26 -> 23
C33: AVERAGE_IF_EYEGLASSES_Y | D33: =AVERAGEIF(A22:A32,"=Y",D22:D32) -> 30.925 | E33: =AVERAGEIF(A22:A32,"=Y",E22:E32) -> 26.825 | F33: =AVERAGEIF(A22:A32,"=Y",F22:F32) -> 25.225 | G33: =AVERAGEIF(A22:A32,"=Y",G22:G32) -> 23.55 | H33: =AVERAGEIF(A22:A32,"=Y",H22:H32) -> 21.85
C34: SD | D34: =_xlfn.STDEV.S(D22,D24,D26,D30) -> 0.37749172 | E34: =_xlfn.STDEV.S(E22,E24,E26,E30) -> 0.88835053 | F34: =_xlfn.STDEV.S(F22,F24,F26,F30) -> 1.0012492 | G34: =_xlfn.STDEV.S(G22,G24,G26,G30) -> 1.3820275 | H34: =_xlfn.STDEV.S(H22,H24,H26,H30) -> 1.6842407
C35: AVERAGE_IF_EYEGLASSES_N | D35: =AVERAGEIF(A22:A32,"=N",D22:D32) -> 31.057143 | E35: =AVERAGEIF(A22:A32,"=N",E22:E32) -> 27.428571 | F35: =AVERAGEIF(A22:A32,"=N",F22:F32) -> 25.485714 | G35: =AVERAGEIF(A22:A32,"=N",G22:G32) -> 23.957143 | H35: =AVERAGEIF(A22:A32,"=N",H22:H32) -> 22.614286
C36: SD | D36: =_xlfn.STDEV.S(D23,D25,D27,D28,D29,D31,D32) -> 0.67294661 | E36: =_xlfn.STDEV.S(E23,E25,E27,E28,E29,E31,E32) -> 0.84204965 | F36: =_xlfn.STDEV.S(F23,F25,F27,F28,F29,F31,F32) -> 0.75372093 | G36: =_xlfn.STDEV.S(G23,G25,G27,G28,G29,G31,G32) -> 1.111841 | H36: =_xlfn.STDEV.S(H23,H25,H27,H28,H29,H31,H32) -> 1.2143978
B38: =B21 -> body temp | C38: =C21 -> ambient temp | D38: =D21 -> 1M | E38: =E21 -> 2M | F38: =F21 -> 3M | G38: =G21 -> 4M | H38: =H21 -> 5M
A39: =Raw_Data!B26 -> N | B39: =Raw_Data!C27 -> 36.6 | C39: =Raw_Data!D27 -> 20 | D39: =Raw_Data!J27 -> 31.3 | E39: =Raw_Data!K27 -> 28 | F39: =Raw_Data!L27 -> 26.5 | G39: =Raw_Data!M27 -> 25 | H39: =Raw_Data!N27 -> 24
A40: =Raw_Data!B27 -> N | B40: =Raw_Data!C28 -> 36.4 | C40: =Raw_Data!D28 -> 20 | D40: =Raw_Data!J28 -> 31 | E40: =Raw_Data!K28 -> 27 | F40: =Raw_Data!L28 -> 25.8 | G40: =Raw_Data!M28 -> 24 | H40: =Raw_Data!N28 -> 23.5
A41: =Raw_Data!B28 -> N | B41: =Raw_Data!C29 -> 36.9 | C41: =Raw_Data!D29 -> 20 | D41: =Raw_Data!J29 -> 31 | E41: =Raw_Data!K29 -> 27.5 | F41: =Raw_Data!L29 -> 26 | G41: =Raw_Data!M29 -> 24.2 | H41: =Raw_Data!N29 -> 22
A42: =Raw_Data!B29 -> Y | B42: =Raw_Data!C30 -> 36.9 | C42: =Raw_Data!D30 -> 20 | D42: =Raw_Data!J30 -> 31.7 | E42: =Raw_Data!K30 -> 28 | F42: =Raw_Data!L30 -> 26.7 | G42: =Raw_Data!M30 -> 25.2 | H42: =Raw_Data!N30 -> 22.5
...

Sheet MLX_R_AVG&SD
A1: Average Values for MLX-R at different ambient temp where eye-glasses is Y | I1: S.D Values for MLX-R at different ambient temp where eye-glasses is Y
A2: =[1]Avarageateachdistance!A1 -> Distance | B2: MLX-R at 16 Degrees Y | C2: MLX-R at 18 Degrees Y | D2: MLX-R at 20 degrees Y | E2: MLX-R at 22 degrees Y | F2: MLX-R at 24 degrees Y | G2: MLX-R at 25 degrees Y | I2: Distance | J2: MLX-R at 16 degrees | K2: MLX-R at 18 Degrees | L2: MLX-R at 20 degrees | M2: MLX-R at 22 degrees | N2: MLX-R at 24 degrees | O2: MLX-R at 25 degrees
A3: 1 | B3: =MLX_R!D16 -> 30.2 | C3: =MLX_R!D33 -> 30.925 | D3: =MLX_R!D47 -> 31.5 | E3: =MLX_R!D63 -> 31.466667 | F3: =MLX_R!D82 -> 32.78 | G3: =MLX_R!D101 -> 32.875 | I3: 1 | J3: =MLX_R!D17 -> 0.79686887 | K3: =MLX_R!D34 -> 0.37749172 | L3: =MLX_R!D48 -> 0.2 | M3: =MLX_R!D64 -> 0.35118846 | N3: =MLX_R!D83 -> 0.39623226 | O3: =MLX_R!D102 -> 0.33040379
A4: 2 | B4: =MLX_R!E16 -> 27.1 | C4: =MLX_R!E33 -> 26.825 | D4: =MLX_R!E47 -> 29.1 | E4: =MLX_R!E63 -> 28.933333 | F4: =MLX_R!E82 -> 31.42 | G4: =MLX_R!E101 -> 30.825 | I4: 2 | J4: =MLX_R!E17 -> 1.2942179 | K4: =MLX_R!E34 -> 0.88835053 | L4: =MLX_R!E48 -> 0.96436508 | M4: =MLX_R!E64 -> 1.2055428 | N4: =MLX_R!E83 -> 1.044988 | O4: =MLX_R!E102 -> 0.38622101
A5: 3 | B5: =MLX_R!F16 -> 24.6 | C5: =MLX_R!F33 -> 25.225 | D5: =MLX_R!F47 -> 27.2 | E5: =MLX_R!F63 -> 27.866667 | F5: =MLX_R!F82 -> 29.88 | G5: =MLX_R!F101 -> 29.875 | I5: 3 | J5: =MLX_R!F17 -> 0.77781746 | K5: =MLX_R!F34 -> 1.0012492 | L5: =MLX_R!F48 -> 0.43588989 | M5: =MLX_R!F64 -> 0.90184995 | N5: =MLX_R!F83 -> 0.87578536 | O5: =MLX_R!F102 -> 0.59090326
A6: 4 | B6: =MLX_R!G16 -> 23.1 | C6: =MLX_R!G33 -> 23.55 | D6: =MLX_R!G47 -> 25.833333 | E6: =MLX_R!G63 -> 27.133333 | F6: =MLX_R!G82 -> 28.4 | G6: =MLX_R!G101 -> 28.975 | I6: 4 | J6: =MLX_R!G17 -> 0.54772256 | K6: =MLX_R!G34 -> 1.3820275 | L6: =MLX_R!G48 -> 0.65064071 | M6: =MLX_R!G64 -> 0.90184995 | N6: =MLX_R!G83 -> 0.46368092 | O6: =MLX_R!G102 -> 0.4425306
A7: 5 | B7: =MLX_R!H16 -> 22.36 | C7: =MLX_R!H33 -> 21.85 | D7: =MLX_R!H47 -> 22.833333 | E7: =MLX_R!H63 -> 25.2 | F7: =MLX_R!H82 -> 27.08 | G7: =MLX_R!H101 -> 28.125 | I7: 5 | J7: =MLX_R!H17 -> 0.49799598 | K7: =MLX_R!H34 -> 1.6842407 | L7: =MLX_R!H48 -> 0.28867513 | M7: =MLX_R!H64 -> 0.96436508 | N7: =MLX_R!H83 -> 0.87578536 | O7: =MLX_R!H102 -> 0.585235
A11: Average Values for MLX-R at different ambient temp where eye-glasses is N | I11: S.D Values for MLX-R at different ambient temp where eye-glasses is N
A12: Distance | B12: MLX-R at 16 Degrees N | C12: MLX-R at 18 Degrees N | D12: MLX-R at 20 degrees N | E12: MLX-R at 22 degrees N | F12: MLX-R at 24 degrees N | G12: MLX-R at 25 degrees N | I12: Distance | J12: MLX-R at 16 degrees | K12: MLX-R at 18 Degrees | L12: MLX-R at 20 degrees | M12: MLX-R at 22 degrees | N12: MLX-R at 24 degrees | O12: MLX-R at 25 degrees
A13: 1 | B13: =MLX_R!D18 -> 30.625 | C13: =MLX_R!D35 -> 31.057143 | D13: =MLX_R!D49 -> 31.1 | E13: =MLX_R!D65 -> 31.642857 | F13: =MLX_R!D84 -> 32.675 | G13: =MLX_R!D103 -> 32.711111 | I13: 1 | J13: =MLX_R!D19 -> 0.6041523 | K13: =MLX_R!D36 -> 0.67294661 | L13: =MLX_R!D50 -> 0.14142136 | M13: =MLX_R!D66 -> 0.63471028 | N13: =MLX_R!D85 -> 1.1247222 | O13: =MLX_R!D104 -> 0.41062283
A14: 2 | B14: =MLX_R!E18 -> 27.285 | C14: =MLX_R!E35 -> 27.428571 | D14: =MLX_R!E49 -> 28.24 | E14: =MLX_R!E65 -> 28.428571 | F14: =MLX_R!E84 -> 31.3 | G14: =MLX_R!E103 -> 30.855556 | I14: 2 | J14: =MLX_R!E19 -> 1.3264668 | K14: =MLX_R!E36 -> 0.84204965 | L14: =MLX_R!E50 -> 1.0784248 | M14: =MLX_R!E66 -> 1.0531133 | N14: =MLX_R!E85 -> 1.029563 | O14: =MLX_R!E104 -> 0.66164777
A15: 3 | B15: =MLX_R!F18 -> 24.95 | C15: =MLX_R!F35 -> 25.485714 | D15: =MLX_R!F49 -> 26.46 | E15: =MLX_R!F65 -> 27.214286 | F15: =MLX_R!F84 -> 29.575 | G15: =MLX_R!F103 -> 29.822222 | I15: 3 | J15: =MLX_R!F19 -> 0.80711125 | K15: =MLX_R!F36 -> 0.75372093 | L15: =MLX_R!F50 -> 0.55497748 | M15: =MLX_R!F66 -> 0.69624845 | N15: =MLX_R!F85 -> 0.78148211 | O15: =MLX_R!F104 -> 0.65722481
A16: 4 | B16: =MLX_R!G18 -> 23.4625 | C16: =MLX_R!G35 -> 23.957143 | D16: =MLX_R!G49 -> 24.98 | E16: =MLX_R!G65 -> 26.557143 | F16: =MLX_R!G84 -> 28.025 | G16: =MLX_R!G103 -> 28.933333 | I16: 4 | J16: =MLX_R!G19 -> 0.51530158 | K16: =MLX_R!G36 -> 1.111841 | L16: =MLX_R!G50 -> 0.91214034 | M16: =MLX_R!G66 -> 0.72997065 | N16: =MLX_R!G85 -> 0.52030211 | O16: =MLX_R!G104 -> 0.50249378
A17: 5 | B17: =MLX_R!H18 -> 22.375 | C17: =MLX_R!H35 -> 22.614286 | D17: =MLX_R!H49 -> 23.12 | E17: =MLX_R!H65 -> 24.242857 | F17: =MLX_R!H84 -> 27.0125 | G17: =MLX_R!H103 -> 27.744444 | I17: 5 | J17: =MLX_R!H19 -> 0.91612538 | K17: =MLX_R!H36 -> 1.2143978 | L17: =MLX_R!H50 -> 0.75960516 | M17: =MLX_R!H66 -> 0.45773771 | N17: =MLX_R!H85 -> 1.0260013 | O17: =MLX_R!H104 -> 0.69661882

Sheet RS_T-10
C1: RS PRO T-10 CAMERA (RS-T10)
A2: =Raw_Data!B2 -> glasses | B2: =MLX_R!B2 -> body temp | C2: =MLX_R!C2 -> ambient temp | D2: =MLX_R!D2 -> 1M | E2: =MLX_R!E2 -> 2M | F2: =MLX_R!F2 -> 3M | G2: =MLX_R!G2 -> 4M | H2: =MLX_R!H2 -> 5M
A3: =Raw_Data!B3 -> N | B3: =MLX_R!B3 -> 36.8 | C3: =MLX_R!C3 -> 16 | D3: =Raw_Data!O3 -> 29.5 | E3: =Raw_Data!P3 -> 27 | F3: =Raw_Data!Q3 -> 26 | G3: =Raw_Data!R3 -> 23 | H3: =Raw_Data!S3 -> 21.7
A4: =Raw_Data!B4 -> Y | B4: =MLX_R!B4 -> 36.8 | C4: =MLX_R!C4 -> 16 | D4: =Raw_Data!O4 -> 30 | E4: =Raw_Data!P4 -> 28.7 | F4: =Raw_Data!Q4 -> 25.7 | G4: =Raw_Data!R4 -> 23.5 | H4: =Raw_Data!S4 -> 22.5
A5: =Raw_Data!B5 -> N | B5: =MLX_R!B5 -> 36.8 | C5: =MLX_R!C5 -> 16 | D5: =Raw_Data!O5 -> 30 | E5: =Raw_Data!P5 -> 28.5 | F5: =Raw_Data!Q5 -> 26.5 | G5: =Raw_Data!R5 -> 24.5 | H5: =Raw_Data!S5 -> 22.5
A6: =Raw_Data!B6 -> Y | B6: =MLX_R!B6 -> 36.6 | C6: =MLX_R!C6 -> 16 | D6: =Raw_Data!O6 -> 32 | E6: =Raw_Data!P6 -> 30 | F6: =Raw_Data!Q6 -> 26 | G6: =Raw_Data!R6 -> 24 | H6: =Raw_Data!S6 -> 22.5
A7: =Raw_Data!B7 -> N | B7: =MLX_R!B7 -> 36.6 | C7: =MLX_R!C7 -> 16 | D7: =Raw_Data!O7 -> 31.5 | E7: =Raw_Data!P7 -> 31 | F7: =Raw_Data!Q7 -> 26.5 | G7: =Raw_Data!R7 -> 24.5 | H7: =Raw_Data!S7 -> 23
A8: =Raw_Data!B8 -> Y | B8: =MLX_R!B8 -> 35.4 | C8: =MLX_R!C8 -> 16 | D8: =Raw_Data!O8 -> 30 | E8: =Raw_Data!P8 -> 27 | F8: =Raw_Data!Q8 -> 25 | G8: =Raw_Data!R8 -> 23 | H8: =Raw_Data!S8 -> 22
A9: =Raw_Data!B9 -> N | B9: =MLX_R!B9 -> 35.4 | C9: =MLX_R!C9 -> 16 | D9: =Raw_Data!O9 -> 30.5 | E9: =Raw_Data!P9 -> 28 | F9: =Raw_Data!Q9 -> 25.5 | G9: =Raw_Data!R9 -> 23 | H9: =Raw_Data!S9 -> 21.5
A10: =Raw_Data!B10 -> N | B10: =MLX_R!B10 -> 36.7 | C10: =MLX_R!C10 -> 16 | D10: =Raw_Data!O10 -> 30 | E10: =Raw_Data!P10 -> 26.7 | F10: =Raw_Data!Q10 -> 25.8 | G10: =Raw_Data!R10 -> 25 | H10: =Raw_Data!S10 -> 23
A11: =Raw_Data!B11 -> N | B11: =MLX_R!B11 -> 36.1 | C11: =MLX_R!C11 -> 16 | D11: =Raw_Data!O11 -> 30.1 | E11: =Raw_Data!P11 -> 28 | F11: =Raw_Data!Q11 -> 26 | G11: =Raw_Data!R11 -> 24 | H11: =Raw_Data!S11 -> 24
A12: =Raw_Data!B12 -> Y | B12: =MLX_R!B12 -> 36.6 | C12: =MLX_R!C12 -> 16 | D12: =Raw_Data!O12 -> 30.1 | E12: =Raw_Data!P12 -> 27.5 | F12: =Raw_Data!Q12 -> 25.8 | G12: =Raw_Data!R12 -> 24.4 | H12: =Raw_Data!S12 -> 23
A13: =Raw_Data!B13 -> N | B13: =MLX_R!B13 -> 36.6 | C13: =MLX_R!C13 -> 16 | D13: =Raw_Data!O13 -> 29.1 | E13: =Raw_Data!P13 -> 28.2 | F13: =Raw_Data!Q13 -> 25.6 | G13: =Raw_Data!R13 -> 24.6 | H13: =Raw_Data!S13 -> 23.5
A14: =Raw_Data!B14 -> Y | B14: =MLX_R!B14 -> 36.4 | C14: =MLX_R!C14 -> 16 | D14: =Raw_Data!O14 -> 29 | E14: =Raw_Data!P14 -> 26 | F14: =Raw_Data!Q14 -> 23.4 | G14: =Raw_Data!R14 -> 21.9 | H14: =Raw_Data!S14 -> 20.5
A15: =Raw_Data!B15 -> N | B15: =MLX_R!B15 -> 36.4 | C15: =MLX_R!C15 -> 16 | D15: =Raw_Data!O15 -> 29.5 | E15: =Raw_Data!P15 -> 26.5 | F15: =Raw_Data!Q15 -> 25.5 | G15: =Raw_Data!R15 -> 23.2 | H15: =Raw_Data!S15 -> 20.5
C16: AVERAGE_IF_EYEGLASSES_Y | D16: =AVERAGEIF(A3:A15,"=Y",D3:D15) -> 30.22 | E16: =AVERAGEIF(A3:A15,"=Y",E3:E15) -> 27.84 | F16: =AVERAGEIF(A3:A15,"=Y",F3:F15) -> 25.18 | G16: =AVERAGEIF(A3:A15,"=Y",G3:G15) -> 23.36 | H16: =AVERAGEIF(A3:A15,"=Y",H3:H15) -> 22.1
C17: SD | D17: =_xlfn.STDEV.S(D4,D6,D8,D12,D14) -> 1.0917875 | E17: =_xlfn.STDEV.S(E4,E6,E8,E12,E14) -> 1.5501613 | F17: =_xlfn.STDEV.S(F4,F6,F8,F12,F14) -> 1.0639549 | G17: =_xlfn.STDEV.S(G4,G6,G8,G12,G14) -> 0.97108187 | H17: =_xlfn.STDEV.S(H4,H6,H8,H12,H14) -> 0.9617692
C18: AVERAGE_IF_EYEGLASSES_N | D18: =AVERAGEIF(A3:A15,"=N",D3:D15) -> 30.025 | E18: =AVERAGEIF(A3:A15,"=N",E3:E15) -> 27.9875 | F18: =AVERAGEIF(A3:A15,"=N",F3:F15) -> 25.925 | G18: =AVERAGEIF(A3:A15,"=N",G3:G15) -> 23.975 | H18: =AVERAGEIF(A3:A15,"=N",H3:H15) -> 22.4625
C19: SD | D19: =_xlfn.STDEV.S(D3,D5,D7,D9,D10,D11,D13,D15) -> 0.73824115 | E19: =_xlfn.STDEV.S(E3,E5,E7,E9,E10,E11,E13,E15) -> 1.4257204 | F19: =_xlfn.STDEV.S(F3,F5,F7,F9,F10,F11,F13,F15) -> 0.40620192 | G19: =_xlfn.STDEV.S(G3,G5,G7,G9,G10,G11,G13,G15) -> 0.80133817 | H19: =_xlfn.STDEV.S(H3,H5,H7,H9,H10,H11,H13,H15) -> 1.1575066
A21: =$A$2 -> glasses | B21: =B2 -> body temp | C21: =C2 -> ambient temp | D21: =D2 -> 1M | E21: =E2 -> 2M | F21: =F2 -> 3M | G21: =G2 -> 4M | H21: =H2 -> 5M
A22: =Raw_Data!B16 -> Y | B22: =MLX_R!B22 -> 36.7 | C22: =MLX_R!C22 -> 18 | D22: =Raw_Data!O16 -> 29.1 | E22: =Raw_Data!P16 -> 27.5 | F22: =Raw_Data!Q16 -> 25.8 | G22: =Raw_Data!R16 -> 24 | H22: =Raw_Data!S16 -> 22.2
A23: =Raw_Data!B17 -> N | B23: =MLX_R!B23 -> 36.7 | C23: =MLX_R!C23 -> 18 | D23: =Raw_Data!O17 -> 29.3 | E23: =Raw_Data!P17 -> 28.1 | F23: =Raw_Data!Q17 -> 26.5 | G23: =Raw_Data!R17 -> 25.2 | H23: =Raw_Data!S17 -> 23.7
A24: =Raw_Data!B18 -> Y | B24: =MLX_R!B24 -> 35.2 | C24: =MLX_R!C24 -> 18 | D24: =Raw_Data!O18 -> 30 | E24: =Raw_Data!P18 -> 28.2 | F24: =Raw_Data!Q18 -> 27 | G24: =Raw_Data!R18 -> 24 | H24: =Raw_Data!S18 -> 20.5
A25: =Raw_Data!B19 -> N | B25: =MLX_R!B25 -> 35.2 | C25: =MLX_R!C25 -> 18 | D25: =Raw_Data!O19 -> 31.5 | E25: =Raw_Data!P19 -> 28.5 | F25: =Raw_Data!Q19 -> 28 | G25: =Raw_Data!R19 -> 25 | H25: =Raw_Data!S19 -> 20.8
A26: =Raw_Data!B20 -> Y | B26: =MLX_R!B26 -> 36.8 | C26: =MLX_R!C26 -> 18 | D26: =Raw_Data!O20 -> 30.5 | E26: =Raw_Data!P20 -> 27.8 | F26: =Raw_Data!Q20 -> 24 | G26: =Raw_Data!R20 -> 22 | H26: =Raw_Data!S20 -> 21
A27: =Raw_Data!B21 -> N | B27: =MLX_R!B27 -> 36.8 | C27: =MLX_R!C27 -> 18 | D27: =Raw_Data!O21 -> 30.5 | E27: =Raw_Data!P21 -> 28.5 | F27: =Raw_Data!Q21 -> 24.5 | G27: =Raw_Data!R21 -> 22.5 | H27: =Raw_Data!S21 -> 22
A28: =Raw_Data!B22 -> N | B28: =MLX_R!B28 -> 36.2 | C28: =MLX_R!C28 -> 18 | D28: =Raw_Data!O22 -> 30 | E28: =Raw_Data!P22 -> 28.5 | F28: =Raw_Data!Q22 -> 26 | G28: =Raw_Data!R22 -> 24.7 | H28: =Raw_Data!S22 -> 23
A29: =Raw_Data!B23 -> N | B29: =MLX_R!B29 -> 36.6 | C29: =MLX_R!C29 -> 18 | D29: =Raw_Data!O23 -> 30 | E29: =Raw_Data!P23 -> 27.4 | F29: =Raw_Data!Q23 -> 25 | G29: =Raw_Data!R23 -> 24.3 | H29: =Raw_Data!S23 -> 22
A30: =Raw_Data!B24 -> Y | B30: =MLX_R!B30 -> 36.8 | C30: =MLX_R!C30 -> 18 | D30: =Raw_Data!O24 -> 29.2 | E30: =Raw_Data!P24 -> 25.5 | F30: =Raw_Data!Q24 -> 26.6 | G30: =Raw_Data!R24 -> 23.3 | H30: =Raw_Data!S24 -> 21.5
A31: =Raw_Data!B25 -> N | B31: =MLX_R!B31 -> 36.8 | C31: =MLX_R!C31 -> 18 | D31: =Raw_Data!O25 -> 29.3 | E31: =Raw_Data!P25 -> 25.5 | F31: =Raw_Data!Q25 -> 26.5 | G31: =Raw_Data!R25 -> 22 | H31: =Raw_Data!S25 -> 23.3
A32: =Raw_Data!B26 -> N | B32: =MLX_R!B32 -> 36.8 | C32: =MLX_R!C32 -> 18 | D32: =Raw_Data!O26 -> 30 | E32: =Raw_Data!P26 -> 27.1 | F32: =Raw_Data!Q26 -> 24.5 | G32: =Raw_Data!R26 -> 23 | H32: =Raw_Data!S26 -> 22.3
C33: AVERAGE_IF_EYEGLASSES_Y | D33: =AVERAGEIF(A22:A32,"=Y",D22:D32) -> 29.7 | E33: =AVERAGEIF(A22:A32,"=Y",E22:E32) -> 27.25 | F33: =AVERAGEIF(A22:A32,"=Y",F22:F32) -> 25.85 | G33: =AVERAGEIF(A22:A32,"=Y",G22:G32) -> 23.325 | H33: =AVERAGEIF(A22:A32,"=Y",H22:H32) -> 21.3
C34: SD | D34: =_xlfn.STDEV.S(D22,D24,D26,D30) -> 0.66833126 | E34: =_xlfn.STDEV.S(E22,E24,E26,E30) -> 1.2013881 | F34: =_xlfn.STDEV.S(F22,F24,F26,F30) -> 1.3304135 | G34: =_xlfn.STDEV.S(G22,G24,G26,G30) -> 0.94295634 | H34: =_xlfn.STDEV.S(H22,H24,H26,H30) -> 0.72571804
C35: AVERAGE_IF_EYEGLASSES_N | D35: =AVERAGEIF(A22:A32,"=N",D22:D32) -> 30.085714 | E35: =AVERAGEIF(A22:A32,"=N",E22:E32) -> 27.657143 | F35: =AVERAGEIF(A22:A32,"=N",F22:F32) -> 25.857143 | G35: =AVERAGEIF(A22:A32,"=N",G22:G32) -> 23.814286 | H35: =AVERAGEIF(A22:A32,"=N",H22:H32) -> 22.442857
C36: SD | D36: =_xlfn.STDEV.S(D23,D25,D27,D28,D29,D31,D32) -> 0.75592895 | E36: =_xlfn.STDEV.S(E23,E25,E27,E28,E29,E31,E32) -> 1.1073349 | F36: =_xlfn.STDEV.S(F23,F25,F27,F28,F29,F31,F32) -> 1.2817399 | G36: =_xlfn.STDEV.S(G23,G25,G27,G28,G29,G31,G32) -> 1.2928374 | H36: =_xlfn.STDEV.S(H23,H25,H27,H28,H29,H31,H32) -> 0.97784993
B38: =B21 -> body temp | C38: =C21 -> ambient temp | D38: =D21 -> 1M | E38: =E21 -> 2M | F38: =F21 -> 3M | G38: =G21 -> 4M | H38: =H21 -> 5M
A39: =Raw_Data!B26 -> N | B39: =MLX_R!B39 -> 36.6 | C39: =MLX_R!C39 -> 20 | D39: =Raw_Data!O27 -> 29.6 | E39: =Raw_Data!P27 -> 27.7 | F39: =Raw_Data!Q27 -> 26.9 | G39: =Raw_Data!R27 -> 26.6 | H39: =Raw_Data!S27 -> 23.7
A40: =Raw_Data!B27 -> N | B40: =MLX_R!B40 -> 36.4 | C40: =MLX_R!C40 -> 20 | D40: =Raw_Data!O28 -> 28.6 | E40: =Raw_Data!P28 -> 27 | F40: =Raw_Data!Q28 -> 24.8 | G40: =Raw_Data!R28 -> 23.8 | H40: =Raw_Data!S28 -> 22.5
A41: =Raw_Data!B28 -> N | B41: =MLX_R!B41 -> 36.9 | C41: =MLX_R!C41 -> 20 | D41: =Raw_Data!O29 -> 29 | E41: =Raw_Data!P29 -> 27.9 | F41: =Raw_Data!Q29 -> 26.2 | G41: =Raw_Data!R29 -> 24.2 | H41: =Raw_Data!S29 -> 22
A42: =Raw_Data!B29 -> Y | B42: =MLX_R!B42 -> 36.9 | C42: =MLX_R!C42 -> 20 | D42: =Raw_Data!O30 -> 29.5 | E42: =Raw_Data!P30 -> 28.4 | F42: =Raw_Data!Q30 -> 27.5 | G42: =Raw_Data!R30 -> 25.7 | H42: =Raw_Data!S30 -> 22.4
...

Sheet RS_T-10_AVG&SD
A1: Average Values for RS_T-10 at different ambient temp where eye-glasses is Y | I1: S.D Values for RS_T-10 at different ambient temp where eye-glasses is Y
A2: =[1]Avarageateachdistance!A1 -> Distance | B2: RS-T10 at 16 Degrees Y | C2: RS-T10 at 18 Degrees Y | D2: RS-T10 at 20 degrees Y | E2: RS-T10 at 22 degrees Y | F2: RS-T10 at 24 degrees Y | G2: RS-T10 at 25 degrees Y | I2: Distance | J2: RS-T10 at 16 degrees | K2: RS-T10 at 18 Degrees | L2: RS-T10at 20 degrees | M2: RS-T10 at 22 degrees | N2: RS-T10 at 24 degrees | O2: RS-T10 at 25 degrees
A3: 1 | B3: ='RS_T-10'!D16 -> 30.22 | C3: ='RS_T-10'!D33 -> 29.7 | D3: ='RS_T-10'!D47 -> 30.266667 | E3: ='RS_T-10'!D63 -> 29.966667 | F3: ='RS_T-10'!D82 -> 31.62 | G3: ='RS_T-10'!D101 -> 30.525 | I3: 1 | J3: ='RS_T-10'!D17 -> 1.0917875 | K3: ='RS_T-10'!D34 -> 0.66833126 | L3: ='RS_T-10'!D48 -> 0.68068593 | M3: ='RS_T-10'!D64 -> 0.28867513 | N3: ='RS_T-10'!D83 -> 0.37013511 | O3: ='RS_T-10'!D102 -> 1.1354148
A4: 2 | B4: ='RS_T-10'!E16 -> 27.84 | C4: ='RS_T-10'!E33 -> 27.25 | D4: ='RS_T-10'!E47 -> 28.733333 | E4: ='RS_T-10'!E63 -> 28.8 | F4: ='RS_T-10'!E82 -> 30.584615 | G4: ='RS_T-10'!E101 -> 29.625 | I4: 2 | J4: ='RS_T-10'!E17 -> 1.5501613 | K4: ='RS_T-10'!E34 -> 1.2013881 | L4: ='RS_T-10'!E48 -> 0.30550505 | M4: ='RS_T-10'!E64 -> 0.52915026 | N4: ='RS_T-10'!E83 -> 0.36331804 | O4: ='RS_T-10'!E102 -> 0.55602758
A5: 3 | B5: ='RS_T-10'!F16 -> 25.18 | C5: ='RS_T-10'!F33 -> 25.85 | D5: ='RS_T-10'!F47 -> 27.1 | E5: ='RS_T-10'!F63 -> 27.766667 | F5: ='RS_T-10'!F82 -> 28.876923 | G5: ='RS_T-10'!F101 -> 28.5 | I5: 3 | J5: ='RS_T-10'!F17 -> 1.0639549 | K5: ='RS_T-10'!F34 -> 1.3304135 | L5: ='RS_T-10'!F48 -> 0.36055513 | M5: ='RS_T-10'!F64 -> 0.81445278 | N5: ='RS_T-10'!F83 -> 0.90443352 | O5: ='RS_T-10'!F102 -> 1.2909944
A6: 4 | B6: ='RS_T-10'!G16 -> 23.36 | C6: ='RS_T-10'!G33 -> 23.325 | D6: ='RS_T-10'!G47 -> 25.033333 | E6: ='RS_T-10'!G63 -> 26.866667 | F6: ='RS_T-10'!G82 -> 27.438462 | G6: ='RS_T-10'!G101 -> 27.3 | I6: 4 | J6: ='RS_T-10'!G17 -> 0.97108187 | K6: ='RS_T-10'!G34 -> 0.94295634 | L6: ='RS_T-10'!G48 -> 0.76376262 | M6: ='RS_T-10'!G64 -> 0.90184995 | N6: ='RS_T-10'!G83 -> 0.29154759 | O6: ='RS_T-10'!G102 -> 2.1150256
A7: 5 | B7: ='RS_T-10'!H16 -> 22.1 | C7: ='RS_T-10'!H33 -> 21.3 | D7: ='RS_T-10'!H47 -> 22.433333 | E7: ='RS_T-10'!H63 -> 24.733333 | F7: ='RS_T-10'!H82 -> 26.353846 | G7: ='RS_T-10'!H101 -> 26.275 | I7: 5 | J7: ='RS_T-10'!H17 -> 0.9617692 | K7: ='RS_T-10'!H34 -> 0.72571804 | L7: ='RS_T-10'!H48 -> 0.057735027 | M7: ='RS_T-10'!H64 -> 0.68068593 | N7: ='RS_T-10'!H83 -> 0.3082207 | O7: ='RS_T-10'!H102 -> 1.1814539
A10: Average Values for RS_T-10 at different ambient temp where eye-glasses is N | I10: S.D Values for RS_T-10 at different ambient temp where eye-glasses is N
A11: Distance | B11: RS-T10 at 16 Degrees N | C11: RS-T10 at 18 Degrees N | D11: RS-T10 at 20 degrees N | E11: RS-T10 at 22 degrees N | F11: RS-T10 at 24 degrees N | G11: RS-T10 at 25 degrees N | I11: Distance | J11: RS-T10 at 16 degrees | K11: RS-T10 at 18 Degrees | L11: RS-T10at 20 degrees | M11: RS-T10 at 22 degrees | N11: RS-T10 at 24 degrees | O11: RS-T10 at 25 degrees
A12: 1 | B12: ='RS_T-10'!D18 -> 30.025 | C12: ='RS_T-10'!D35 -> 30.085714 | D12: ='RS_T-10'!D49 -> 29.54 | E12: ='RS_T-10'!D65 -> 29.957143 | F12: ='RS_T-10'!D84 -> 31.4625 | G12: ='RS_T-10'!D103 -> 30.855556 | I12: 1 | J12: ='RS_T-10'!D19 -> 0.73824115 | K12: ='RS_T-10'!D36 -> 0.75592895 | L12: ='RS_T-10'!D66 -> 0.47559487 | M12: ='RS_T-10'!D66 -> 0.47559487 | N12: ='RS_T-10'!D85 -> 0.4470139 | O12: ='RS_T-10'!D104 -> 0.68940393
A13: 2 | B13: ='RS_T-10'!E18 -> 27.9875 | C13: ='RS_T-10'!E35 -> 27.657143 | D13: ='RS_T-10'!E49 -> 27.92 | E13: ='RS_T-10'!E65 -> 28.285714 | F13: ='RS_T-10'!E84 -> 30.525 | G13: ='RS_T-10'!E103 -> 29.7 | I13: 2 | J13: ='RS_T-10'!E19 -> 1.4257204 | K13: ='RS_T-10'!E36 -> 1.1073349 | L13: ='RS_T-10'!E66 -> 0.64142698 | M13: ='RS_T-10'!E66 -> 0.64142698 | N13: ='RS_T-10'!E85 -> 0.50355876 | O13: ='RS_T-10'!E104 -> 0.89861004
A14: 3 | B14: ='RS_T-10'!F18 -> 25.925 | C14: ='RS_T-10'!F35 -> 25.857143 | D14: ='RS_T-10'!F49 -> 26.24 | E14: ='RS_T-10'!F65 -> 27.185714 | F14: ='RS_T-10'!F84 -> 28.7 | G14: ='RS_T-10'!F103 -> 28.666667 | I14: 3 | J14: ='RS_T-10'!F19 -> 0.40620192 | K14: ='RS_T-10'!F36 -> 1.2817399 | L14: ='RS_T-10'!F66 -> 0.75150642 | M14: ='RS_T-10'!F66 -> 0.75150642 | N14: ='RS_T-10'!F85 -> 0.61411958 | O14: ='RS_T-10'!F104 -> 0.99624294
A15: 4 | B15: ='RS_T-10'!G18 -> 23.975 | C15: ='RS_T-10'!G35 -> 23.814286 | D15: ='RS_T-10'!G49 -> 24.68 | E15: ='RS_T-10'!G65 -> 25.942857 | F15: ='RS_T-10'!G84 -> 27.4625 | G15: ='RS_T-10'!G103 -> 27.288889 | I15: 4 | J15: ='RS_T-10'!G19 -> 0.80133817 | K15: ='RS_T-10'!G36 -> 1.2928374 | L15: ='RS_T-10'!G66 -> 0.99976188 | M15: ='RS_T-10'!G66 -> 0.99976188 | N15: ='RS_T-10'!G85 -> 0.68230178 | O15: ='RS_T-10'!G104 -> 1.288841
A16: 5 | B16: ='RS_T-10'!H18 -> 22.4625 | C16: ='RS_T-10'!H35 -> 22.442857 | D16: ='RS_T-10'!H49 -> 22.48 | E16: ='RS_T-10'!H65 -> 24.214286 | F16: ='RS_T-10'!H84 -> 26.325 | G16: ='RS_T-10'!H103 -> 26.311111 | I16: 5 | J16: ='RS_T-10'!H19 -> 1.1575066 | K16: ='RS_T-10'!H36 -> 0.97784993 | L16: ='RS_T-10'!H66 -> 0.72670162 | M16: ='RS_T-10'!H66 -> 0.72670162 | N16: ='RS_T-10'!H85 -> 0.80133817 | O16: ='RS_T-10'!H104 -> 1.0030509

Sheet AVG_AB_TEMP_Y

Sheet AVG_AB_TEMP_N

Sheet AV&SD@25degree_AB_T

Sheet AV&SD@16degree_AB_T

Sheet comparison _MLX-P_MLX-R_RS-T10

Sheet ALL ABT

Sheet RAWDATA SORTED BY_EYEglasses
A1: =Raw_Data!A1 -> 0 | B1: =Raw_Data!B1 -> 0 | C1: =Raw_Data!C1 -> 0 | D1: =Raw_Data!D1 -> 0 | E1: MLX-P | F1: =Raw_Data!F1 -> 0 | G1: =Raw_Data!G1 -> 0 | H1: =Raw_Data!H1 -> 0 | I1: =Raw_Data!I1 -> 0 | J1: MLX-R | K1: =Raw_Data!K1 -> 0 | L1: =Raw_Data!L1 -> 0 | M1: =Raw_Data!M1 -> 0 | N1: =Raw_Data!N1 -> 0 | O1: RS-T10 | P1: =Raw_Data!P1 -> 0 | Q1: =Raw_Data!Q1 -> 0 | R1: =Raw_Data!R1 -> 0 | S1: =Raw_Data!S1 -> 0
A2: =Raw_Data!A2 -> ID | B2: =Raw_Data!B2 -> glasses | C2: =Raw_Data!C2 -> body temp | D2: =Raw_Data!D2 -> ambient temp | E2: =Raw_Data!E2 -> 1M | F2: =Raw_Data!F2 -> 2M | G2: =Raw_Data!G2 -> 3M | H2: =Raw_Data!H2 -> 4M | ... S2: =Raw_Data!S2 -> 5M
A3: =Raw_Data!A3 -> 1 | B3: =Raw_Data!B3 -> N | C3: =Raw_Data!C3 -> 36.8 | D3: =Raw_Data!D3 -> 16 | E3: =Raw_Data!E3 -> 30.3 | F3: =Raw_Data!F3 -> 25.5 | G3: =Raw_Data!G3 -> 23 | H3: =Raw_Data!H3 -> 22.06 | ... S3: =Raw_Data!S3 -> 21.7
A4: =Raw_Data!A4 -> 2 | B4: =Raw_Data!B5 -> N | C4: =Raw_Data!C5 -> 36.8 | D4: =Raw_Data!D5 -> 16 | E4: =Raw_Data!E5 -> 30.3 | F4: =Raw_Data!F5 -> 30 | G4: =Raw_Data!G5 -> 25.5 | H4: =Raw_Data!H5 -> 23.5 | I4: =Raw_Data!I5 -> 22 | ... S4: =Raw_Data!S5 -> 22.5
A5: =Raw_Data!A5 -> 3 | B5: =Raw_Data!B7 -> N | C5: =Raw_Data!C7 -> 36.6 | D5: =Raw_Data!D7 -> 16 | E5: =Raw_Data!E7 -> 31 | F5: =Raw_Data!F7 -> 29.1 | G5: =Raw_Data!G7 -> 25.5 | H5: =Raw_Data!H7 -> 23.5 | I5: =Raw_Data!I7 -> 22 | ... S5: =Raw_Data!S7 -> 23
A6: =Raw_Data!A6 -> 4 | B6: =Raw_Data!B9 -> N | C6: =Raw_Data!C9 -> 35.4 | D6: =Raw_Data!D9 -> 16 | E6: =Raw_Data!E9 -> 30.5 | F6: =Raw_Data!F9 -> 26 | G6: =Raw_Data!G9 -> 23.5 | H6: =Raw_Data!H9 -> 22.7 | I6: =Raw_Data!I9 -> 21 | ... S6: =Raw_Data!S9 -> 21.5
A7: =Raw_Data!A7 -> 5 | B7: =Raw_Data!B10 -> N | C7: =Raw_Data!C10 -> 36.7 | D7: =Raw_Data!D10 -> 16 | E7: =Raw_Data!E10 -> 30 | F7: =Raw_Data!F10 -> 26 | G7: =Raw_Data!G10 -> 24.3 | H7: =Raw_Data!H10 -> 22.9 | I7: =Raw_Data!I10 -> 21.5 | ... S7: =Raw_Data!S10 -> 23
A8: =Raw_Data!A8 -> 6 | B8: =Raw_Data!B11 -> N | C8: =Raw_Data!C11 -> 36.1 | D8: =Raw_Data!D11 -> 16 | E8: =Raw_Data!E11 -> 30 | F8: =Raw_Data!F11 -> 26.7 | G8: =Raw_Data!G11 -> 24.5 | H8: =Raw_Data!H11 -> 23.8 | I8: =Raw_Data!I11 -> 22.1 | ... S8: =Raw_Data!S11 -> 24
A9: =Raw_Data!A9 -> 7 | B9: =Raw_Data!B13 -> N | C9: =Raw_Data!C13 -> 36.6 | D9: =Raw_Data!D13 -> 16 | E9: =Raw_Data!E13 -> 30 | F9: =Raw_Data!F13 -> 26.32 | G9: =Raw_Data!G13 -> 23.9 | H9: =Raw_Data!H13 -> 22.7 | I9: =Raw_Data!I13 -> 21.9 | ... S9: =Raw_Data!S13 -> 23.5
A10: =Raw_Data!A10 -> 8 | B10: =Raw_Data!B15 -> N | C10: =Raw_Data!C15 -> 36.4 | D10: =Raw_Data!D15 -> 16 | E10: =Raw_Data!E15 -> 29.5 | F10: =Raw_Data!F15 -> 24.5 | G10: =Raw_Data!G15 -> 24.4 | H10: =Raw_Data!H15 -> 23.5 | I10: =Raw_Data!I15 -> 22.7 | ... S10: =Raw_Data!S15 -> 20.5
A11: =Raw_Data!A11 -> 9 | B11: =Raw_Data!B17 -> N | C11: =Raw_Data!C17 -> 36.7 | D11: =Raw_Data!D17 -> 18 | E11: =Raw_Data!E17 -> 30.2 | F11: =Raw_Data!F17 -> 26.5 | G11: =Raw_Data!G17 -> 24.8 | H11: =Raw_Data!H17 -> 23.6 | I11: =Raw_Data!I17 -> 22.8 | ... S11: =Raw_Data!S17 -> 23.7
A12: =Raw_Data!A12 -> 10 | B12: =Raw_Data!B19 -> N | C12: =Raw_Data!C19 -> 35.2 | D12: =Raw_Data!D19 -> 18 | E12: =Raw_Data!E19 -> 31.6 | F12: =Raw_Data!F19 -> 28 | G12: =Raw_Data!G19 -> 26.5 | H12: =Raw_Data!H19 -> 24.5 | I12: =Raw_Data!I19 -> 20.5 | ... S12: =Raw_Data!S19 -> 20.8
A13: =Raw_Data!A13 -> 11 | B13: =Raw_Data!B21 -> N | C13: =Raw_Data!C21 -> 36.8 | D13: =Raw_Data!D21 -> 18 | E13: =Raw_Data!E21 -> 30.8 | F13: =Raw_Data!F21 -> 27.3 | G13: =Raw_Data!G21 -> 24.5 | H13: =Raw_Data!H21 -> 21.2 | I13: =Raw_Data!I21 -> 21 | ... S13: =Raw_Data!S21 -> 22
A14: =Raw_Data!A14 -> 12 | B14: =Raw_Data!B22 -> N | C14: =Raw_Data!C22 -> 36.2 | D14: =Raw_Data!D22 -> 18 | E14: =Raw_Data!E22 -> 31.1 | F14: =Raw_Data!F22 -> 27.5 | G14: =Raw_Data!G22 -> 25.1 | H14: =Raw_Data!H22 -> 24.2 | I14: =Raw_Data!I22 -> 23.6 | ... S14: =Raw_Data!S22 -> 23
A15: =Raw_Data!A15 -> 13 | B15: =Raw_Data!B23 -> N | C15: =Raw_Data!C23 -> 36.6 | D15: =Raw_Data!D23 -> 18 | E15: =Raw_Data!E23 -> 29.9 | F15: =Raw_Data!F23 -> 26.5 | G15: =Raw_Data!G23 -> 24.5 | H15: =Raw_Data!H23 -> 23.5 | I15: =Raw_Data!I23 -> 22.4 | ... S15: =Raw_Data!S23 -> 22
A16: =Raw_Data!A16 -> 14 | B16: =Raw_Data!B25 -> N | C16: =Raw_Data!C25 -> 36.8 | D16: =Raw_Data!D25 -> 18 | E16: =Raw_Data!E25 -> 30.7 | F16: =Raw_Data!F25 -> 25.4 | G16: =Raw_Data!G25 -> 24.9 | H16: =Raw_Data!H25 -> 23.8 | I16: =Raw_Data!I25 -> 23.2 | ... S16: =Raw_Data!S25 -> 23.3
A17: =Raw_Data!A17 -> 15 | B17: =Raw_Data!B26 -> N | C17: =Raw_Data!C26 -> 36.8 | D17: =Raw_Data!D26 -> 18 | E17: =Raw_Data!E26 -> 29.9 | F17: =Raw_Data!F26 -> 26.3 | G17: =Raw_Data!G26 -> 24.2 | H17: =Raw_Data!H26 -> 23.1 | I17: =Raw_Data!I26 -> 22.4 | ... S17: =Raw_Data!S26 -> 22.3
A18: =Raw_Data!A18 -> 16 | B18: =Raw_Data!B27 -> N | C18: =Raw_Data!C27 -> 36.6 | D18: =Raw_Data!D27 -> 20 | E18: =Raw_Data!E27 -> 30.5 | F18: =Raw_Data!F27 -> 27.6 | G18: =Raw_Data!G27 -> 25.8 | H18: =Raw_Data!H27 -> 24.5 | I18: =Raw_Data!I27 -> 23.5 | ... S18: =Raw_Data!S27 -> 23.7
A19: =Raw_Data!A19 -> 17 | B19: =Raw_Data!B28 -> N | C19: =Raw_Data!C28 -> 36.4 | D19: =Raw_Data!D28 -> 20 | E19: =Raw_Data!E28 -> 30.6 | F19: =Raw_Data!F28 -> 26.4 | G19: =Raw_Data!G28 -> 25.5 | H19: =Raw_Data!H28 -> 24.6 | I19: =Raw_Data!I28 -> 23 | ... S19: =Raw_Data!S28 -> 22.5
A20: =Raw_Data!A20 -> 18 | B20: =Raw_Data!B30 -> N | C20: =Raw_Data!C30 -> 36.9 | D20: =Raw_Data!D30 -> 20 | E20: =Raw_Data!E30 -> 30.8 | F20: =Raw_Data!F30 -> 28.5 | G20: =Raw_Data!G30 -> 26 | H20: =Raw_Data!H30 -> 25 | I20: =Raw_Data!I30 -> 22.8 | ... S20: =Raw_Data!S30 -> 22.4
A21: =Raw_Data!A21 -> 19 | B21: =Raw_Data!B32 -> N | C21: =Raw_Data!C32 -> 36.4 | D21: =Raw_Data!D32 -> 20 | E21: =Raw_Data!E32 -> 31 | F21: =Raw_Data!F32 -> 28.4 | G21: =Raw_Data!G32 -> 26.8 | H21: =Raw_Data!H32 -> 25 | I21: =Raw_Data!I32 -> 22.5 | ... S21: =Raw_Data!S32 -> 22.4
A22: =Raw_Data!A22 -> 20 | B22: =Raw_Data!B34 -> N | C22: =Raw_Data!C34 -> 36.8 | D22: =Raw_Data!D34 -> 20 | E22: =Raw_Data!E34 -> 31.7 | F22: =Raw_Data!F34 -> 29.2 | G22: =Raw_Data!G34 -> 27.5 | H22: =Raw_Data!H34 -> 26 | I22: =Raw_Data!I34 -> 23.3 | ... S22: =Raw_Data!S34 -> 22.5
A23: =Raw_Data!A23 -> 21 | B23: =Raw_Data!B36 -> N | C23: =Raw_Data!C36 -> 36.7 | D23: =Raw_Data!D36 -> 22 | E23: =Raw_Data!E36 -> 30.9 | F23: =Raw_Data!F36 -> 27.2 | G23: =Raw_Data!G36 -> 26.8 | H23: =Raw_Data!H36 -> 25.5 | I23: =Raw_Data!I36 -> 24 | ... S23: =Raw_Data!S36 -> 24.5
A24: =Raw_Data!A24 -> 22 | B24: =Raw_Data!B37 -> N | C24: =Raw_Data!C37 -> 36.8 | D24: =Raw_Data!D37 -> 22 | E24: =Raw_Data!E37 -> 31.7 | F24: =Raw_Data!F37 -> 28.7 | G24: =Raw_Data!G37 -> 26.5 | H24: =Raw_Data!H37 -> 25.6 | I24: =Raw_Data!I37 -> 24 | ... S24: =Raw_Data!S37 -> 24.1
A25: =Raw_Data!A25 -> 23 | B25: =Raw_Data!B38 -> N | C25: =Raw_Data!C38 -> 36.6 | D25: =Raw_Data!D38 -> 22 | E25: =Raw_Data!E38 -> 30.5 | F25: =Raw_Data!F38 -> 26.7 | G25: =Raw_Data!G38 -> 26 | H25: =Raw_Data!H38 -> 25.5 | I25: =Raw_Data!I38 -> 24 | ... S25: =Raw_Data!S38 -> 23
A26: =Raw_Data!A26 -> 24 | B26: =Raw_Data!B39 -> N | C26: =Raw_Data!C39 -> 36.9 | D26: =Raw_Data!D39 -> 22 | E26: =Raw_Data!E39 -> 31.4 | F26: =Raw_Data!F39 -> 28.2 | G26: =Raw_Data!G39 -> 26.5 | H26: =Raw_Data!H39 -> 26 | I26: =Raw_Data!I39 -> 23.3 | ... S26: =Raw_Data!S39 -> 24
A27: =Raw_Data!A27 -> 25 | B27: =Raw_Data!B40 -> N | C27: =Raw_Data!C40 -> 36.7 | D27: =Raw_Data!D40 -> 22 | E27: =Raw_Data!E40 -> 30.7 | F27: =Raw_Data!F40 -> 28.1 | G27: =Raw_Data!G40 -> 27 | H27: =Raw_Data!H40 -> 26.2 | I27: =Raw_Data!I40 -> 24 | ... S27: =Raw_Data!S40 -> 25
A28: =Raw_Data!A28 -> 26 | B28: =Raw_Data!B42 -> N | C28: =Raw_Data!C42 -> 36.8 | D28: =Raw_Data!D42 -> 22 | E28: =Raw_Data!E42 -> 30.99 | F28: =Raw_Data!F42 -> 29 | G28: =Raw_Data!G42 -> 27.4 | H28: =Raw_Data!H42 -> 26.8 | I28: =Raw_Data!I42 -> 24.6 | ... S28: =Raw_Data!S42 -> 24.2
A29: =Raw_Data!A29 -> 27 | B29: =Raw_Data!B44 -> N | C29: =Raw_Data!C44 -> 36.9 | D29: =Raw_Data!D44 -> 22 | E29: =Raw_Data!E44 -> 31.5 | F29: =Raw_Data!F44 -> 29.4 | G29: =Raw_Data!G44 -> 28.8 | H29: =Raw_Data!H44 -> 27.5 | I29: =Raw_Data!I44 -> 26 | ... S29: =Raw_Data!S44 -> 25.5
A30: =Raw_Data!A30 -> 28 | B30: =Raw_Data!B46 -> N | C30: =Raw_Data!C46 -> 36.9 | D30: =Raw_Data!D46 -> 24 | E30: =Raw_Data!E46 -> 32 | F30: =Raw_Data!F46 -> 30.5 | G30: =Raw_Data!G46 -> 27.9 | H30: =Raw_Data!H46 -> 27.6 | I30: =Raw_Data!I46 -> 26 | ... S30: =Raw_Data!S46 -> 26.5
A31: =Raw_Data!A31 -> 29 | B31: =Raw_Data!B47 -> N | C31: =Raw_Data!C47 -> 36.7 | D31: =Raw_Data!D47 -> 24 | E31: =Raw_Data!E47 -> 34.4 | F31: =Raw_Data!F47 -> 32 | G31: =Raw_Data!G47 -> 28.7 | H31: =Raw_Data!H47 -> 27.4 | I31: =Raw_Data!I47 -> 27 | ... S31: =Raw_Data!S47 -> 28
A32: =Raw_Data!A32 -> 30 | B32: =Raw_Data!B49 -> N | C32: =Raw_Data!C49 -> 36.5 | D32: =Raw_Data!D49 -> 24 | E32: =Raw_Data!E49 -> 32.8 | F32: =Raw_Data!F49 -> 32 | G32: =Raw_Data!G49 -> 28.2 | H32: =Raw_Data!H49 -> 26.8 | I32: =Raw_Data!I49 -> 26.2 | ... S32: =Raw_Data!S49 -> 26.2
A33: =Raw_Data!A33 -> 31 | B33: =Raw_Data!B51 -> N | C33: =Raw_Data!C51 -> 36.9 | D33: =Raw_Data!D51 -> 24 | E33: =Raw_Data!E51 -> 32.8 | F33: =Raw_Data!F51 -> 30.7 | G33: =Raw_Data!G51 -> 29.5 | H33: =Raw_Data!H51 -> 28.8 | I33: =Raw_Data!I51 -> 27.4 | ... S33: =Raw_Data!S51 -> 26.5
A34: =Raw_Data!A34 -> 32 | B34: =Raw_Data!B53 -> N | C34: =Raw_Data!C53 -> 36.9 | D34: =Raw_Data!D53 -> 24 | E34: =Raw_Data!E53 -> 32.8 | F34: =Raw_Data!F53 -> 31.8 | G34: =Raw_Data!G53 -> 30.5 | H34: =Raw_Data!H53 -> 28.8 | I34: =Raw_Data!I53 -> 28 | ... S34: =Raw_Data!S53 -> 26
A35: =Raw_Data!A35 -> 33 | B35: =Raw_Data!B54 -> N | C35: =Raw_Data!C54 -> 36.6 | D35: =Raw_Data!D54 -> 24 | E35: =Raw_Data!E54 -> 32.5 | F35: =Raw_Data!F54 -> 31 | G35: =Raw_Data!G54 -> 30.2 | H35: =Raw_Data!H54 -> 27.8 | I35: =Raw_Data!I54 -> 27 | ... S35: =Raw_Data!S54 -> 25.7
A36: =Raw_Data!A36 -> 34 | B36: =Raw_Data!B56 -> N | C36: =Raw_Data!C56 -> 36.8 | D36: =Raw_Data!D56 -> 24 | E36: =Raw_Data!E56 -> 32.2 | F36: =Raw_Data!F56 -> 30.4 | G36: =Raw_Data!G56 -> 29.8 | H36: =Raw_Data!H56 -> 27.6 | I36: =Raw_Data!I56 -> 27 | ... S36: =Raw_Data!S56 -> 26.8
A37: =Raw_Data!A37 -> 35 | B37: =Raw_Data!B57 -> N | C37: =Raw_Data!C57 -> 36.9 | D37: =Raw_Data!D57 -> 24 | E37: =Raw_Data!E57 -> 32.5 | F37: =Raw_Data!F57 -> 30.2 | G37: =Raw_Data!G57 -> 28.9 | H37: =Raw_Data!H57 -> 27.5 | I37: =Raw_Data!I57 -> 26.9 | ... S37: =Raw_Data!S57 -> 26.6
A38: =Raw_Data!A38 -> 36 | B38: =Raw_Data!B58 -> N | C38: =Raw_Data!C58 -> 36.7 | D38: =Raw_Data!D58 -> 25 | E38: =Raw_Data!E58 -> 32.1 | F38: =Raw_Data!F58 -> 29.8 | G38: =Raw_Data!G58 -> 28.4 | H38: =Raw_Data!H58 -> 27.5 | I38: =Raw_Data!I58 -> 26 | ... S38: =Raw_Data!S58 -> 25.9
A39: =Raw_Data!A39 -> 37 | B39: =Raw_Data!B60 -> N | C39: =Raw_Data!C60 -> 36.8 | D39: =Raw_Data!D60 -> 25 | E39: =Raw_Data!E60 -> 32.5 | F39: =Raw_Data!F60 -> 30.1 | G39: =Raw_Data!G60 -> 28.8 | H39: =Raw_Data!H60 -> 27.9 | I39: =Raw_Data!I60 -> 27.2 | ... S39: =Raw_Data!S60 -> 26.3
A40: =Raw_Data!A40 -> 38 | B40: =Raw_Data!B62 -> N | C40: =Raw_Data!C62 -> 36.9 | D40: =Raw_Data!D62 -> 25 | E40: =Raw_Data!E62 -> 32 | F40: =Raw_Data!F62 -> 30.6 | G40: =Raw_Data!G62 -> 30.4 | H40: =Raw_Data!H62 -> 29 | I40: =Raw_Data!I62 -> 28.3 | ... S40: =Raw_Data!S62 -> 27.2
...

Sheet MLX-P_WorWT_EYEglasses
B1: WITHOUT GLASSES | J1: WITH GLASSES
B2: 1M | C2: ='RAWDATA SORTED BY_EYEglasses'!F2 -> 2M | D2: ='RAWDATA SORTED BY_EYEglasses'!G2 -> 3M | E2: ='RAWDATA SORTED BY_EYEglasses'!H2 -> 4M | F2: ='RAWDATA SORTED BY_EYEglasses'!I2 -> 5M | K2: =B2 -> 1M | L2: =C2 -> 2M | M2: =D2 -> 3M | N2: =E2 -> 4M | O2: =F2 -> 5M
B3: ='RAWDATA SORTED BY_EYEglasses'!E3 -> 30.3 | C3: ='RAWDATA SORTED BY_EYEglasses'!F3 -> 25.5 | D3: ='RAWDATA SORTED BY_EYEglasses'!G3 -> 23 | E3: ='RAWDATA SORTED BY_EYEglasses'!H3 -> 22.06 | F3: ='RAWDATA SORTED BY_EYEglasses'!I3 -> 21.5 | K3: ='RAWDATA SORTED BY_EYEglasses'!E47 -> 30 | L3: ='RAWDATA SORTED BY_EYEglasses'!F47 -> 29.5 | M3: ='RAWDATA SORTED BY_EYEglasses'!G47 -> 26 | N3: ='RAWDATA SORTED BY_EYEglasses'!H47 -> 24.5 | O3: ='RAWDATA SORTED BY_EYEglasses'!I47 -> 22.5
B4: ='RAWDATA SORTED BY_EYEglasses'!E4 -> 30.3 | C4: ='RAWDATA SORTED BY_EYEglasses'!F4 -> 30 | D4: ='RAWDATA SORTED BY_EYEglasses'!G4 -> 25.5 | E4: ='RAWDATA SORTED BY_EYEglasses'!H4 -> 23.5 | F4: ='RAWDATA SORTED BY_EYEglasses'!I4 -> 22 | K4: ='RAWDATA SORTED BY_EYEglasses'!E48 -> 30.5 | L4: ='RAWDATA SORTED BY_EYEglasses'!F48 -> 27.9 | M4: ='RAWDATA SORTED BY_EYEglasses'!G48 -> 25.2 | N4: ='RAWDATA SORTED BY_EYEglasses'!H48 -> 23 | O4: ='RAWDATA SORTED BY_EYEglasses'!I48 -> 21.7
B5: ='RAWDATA SORTED BY_EYEglasses'!E5 -> 31 | C5: ='RAWDATA SORTED BY_EYEglasses'!F5 -> 29.1 | D5: ='RAWDATA SORTED BY_EYEglasses'!G5 -> 25.5 | E5: ='RAWDATA SORTED BY_EYEglasses'!H5 -> 23.5 | F5: ='RAWDATA SORTED BY_EYEglasses'!I5 -> 22 | K5: ='RAWDATA SORTED BY_EYEglasses'!E49 -> 30 | L5: ='RAWDATA SORTED BY_EYEglasses'!F49 -> 25.5 | M5: ='RAWDATA SORTED BY_EYEglasses'!G49 -> 23 | N5: ='RAWDATA SORTED BY_EYEglasses'!H49 -> 22.5 | O5: ='RAWDATA SORTED BY_EYEglasses'!I49 -> 21.5
